Workbook

Sheet membres_infos
A1: Nom Complet | B1: Téléphone | C1: Quartier
A2: MENGUE François Xavier
A3: EBOGO BIKOULA Gilbert
A4: IPOULE Michel Landry
A5: OMGBA FOUDA Simon Pierre
A6: 100500
A7: AUTRES / FETE
A8: MBA ENYOUGOU Bernard
A9: MIONG RIGOBERT Dieudonné
A10: LIKENG BALEBA
A11: EWALA Jacques Philippe
A12: MBAMBA NSOA Jean Paul
A13: 600000
... A21: TSANGA TSANGA Christol
A22: =B44/B37
A23: FOTUE KAMGUE Kevin
A24: BANGA NNA Israel
A25: 38000
A26: ABENG ZE Jean Claude
A27: ITOP Samuel
A28: ETOA Yves
A29: ONDOA Jean
A30: BUREAU
A31: ESSALA Etienne
A32: OMGBA MIMBOE Gaetan
A33: BISSAI BI NOMBO Fabrice
A34: ONANA NKADA Laurent S.

Sheet ep+int
A1: NOMS ET PRENOMS | B1: EP AOUT | C1: EP AOUT+INT | D1: EP SEPT | E1: CUMUL1 | F1: EP +INT1 | G1: EP OCTO | H1: CUMUL2 | I1: EP +INT2 | J1: EP NOV | K1: CUMUL3 | L1: EP +INT3 | M1: EP DEC | N1: CUMUL4 | O1: EP+INT | P1: EP JANV | Q1: CUMUL5 | R1: EP+INT4 | S1: EP FEV | T1: CUMUL6 | U1: EP+INT5 | V1: EP MARS | W1: CUMUL7 | X1: EP+INT6 | Y1: EP AVRI | Z1: CUMUL8 | AA1: EP+INT7 | AB1: EP MAI | AC1: CUMUL9 | AD1: EP+INT8 | AE1: EP JUIN | AF1: CUMUL10 | AG1: EP+INT9 | AH1: EP JUILL | AI1: CUMUL11 | AJ1: EP+INT94 | AK1: EP TOTALE | AL1: INTERETS | AM1: N A P | AO1: N° | AP1: NOM | AQ1: EPARGNE | AR1: INTERET | AS1: TOTAL | AU1: REM PRETS
A2: ABENG ZE Jean Claude | B2: 94000 | C2: =B2*(1+(#REF!)/(B$37)) | E2: =+D2+C2 | F2: =+E2*(1+(#REF!)/(E$37)) | H2: =+F2+G2 | I2: =+H2*(1+(#REF!)/(H$37)) | K2: =+I2+J2 | L2: =+K2*(1+(#REF!)/(K$37)) | N2: =+L2+M2 | O2: =+N2*(1+(#REF!)/(N$37)) | Q2: =+O2+P2 | R2: =+Q2*(1+(#REF!)/(Q$37)) | T2: =+R2+S2 | U2: =+T2*(1+(#REF!)/(T$37)) | W2: =+U2+V2 | X2: =+W2*(1+(#REF!)/(W$37)) | Z2: =+X2+Y2 | AA2: =+Z2*(1+(#REF!)/(Z$37)) | AC2: =+AA2+AB2 | AD2: =+AC2*(1+(#REF!)/(AC$37)) | AF2: =+AD2+AE2 | AG2: =+AF2*(1+(#REF!)/(AF$37)) | AI2: =+AG2+AH2 | AJ2: =+AI2*(1+(#REF!)/(AI$37)) | AK2: =B2+D2+G2+J2+M2+P2+S2+V2+Y2+AB2+AE2+AH2 | AL2: =-AK2+AJ2 | AM2: =Tableau44[[#This Row],[EP TOTALE]]+Tableau44[[#This Row],[INTERETS]] | AO2: 1 | AP2: ABENG ZE Jean Claude | AQ2: 94000 | AR2: 16106.292 | AS2: 110106.29
A3: BANGA NNA Israel | B3: 129000 | C3: =B3*(1+(#REF!)/(B$37)) | E3: =+D3+C3 | F3: =+E3*(1+(#REF!)/(E$37)) | H3: =+F3+G3 | I3: =+H3*(1+(#REF!)/(H$37)) | K3: =+I3+J3 | L3: =+K3*(1+(#REF!)/(K$37)) | N3: =+L3+M3 | O3: =+N3*(1+(#REF!)/(N$37)) | Q3: =+O3+P3 | R3: =+Q3*(1+(#REF!)/(Q$37)) | T3: =+R3+S3 | U3: =+T3*(1+(#REF!)/(T$37)) | W3: =+U3+V3 | X3: =+W3*(1+(#REF!)/(W$37)) | Z3: =+X3+Y3 | AA3: =+Z3*(1+(#REF!)/(Z$37)) | AC3: =+AA3+AB3 | AD3: =+AC3*(1+(#REF!)/(AC$37)) | AF3: =+AD3+AE3 | AG3: =+AF3*(1+(#REF!)/(AF$37)) | AI3: =+AG3+AH3 | AJ3: =+AI3*(1+(#REF!)/(AI$37)) | AK3: =B3+D3+G3+J3+M3+P3+S3+V3+Y3+AB3+AE3+AH3 | AL3: =-AK3+AJ3 | AM3: =Tableau44[[#This Row],[EP TOTALE]]+Tableau44[[#This Row],[INTERETS]] | AO3: 2 | AP3: BANGA NNA Israel | AQ3: 329000 | AR3: 49454.331 | AS3: 378454.33
A4: BISSAI BI NOMBO Fabrice | B4: 107000 | C4: =B4*(1+(#REF!)/(B$37)) | E4: =+D4+C4 | F4: =+E4*(1+(#REF!)/(E$37)) | H4: =+F4+G4 | I4: =+H4*(1+(#REF!)/(H$37)) | K4: =+I4+J4 | L4: =+K4*(1+(#REF!)/(K$37)) | M4: 7000 | N4: =+L4+M4 | O4: =+N4*(1+(#REF!)/(N$37)) | P4: 7000 | Q4: =+O4+P4 | R4: =+Q4*(1+(#REF!)/(Q$37)) | S4: 7000 | T4: =+R4+S4 | U4: =+T4*(1+(#REF!)/(T$37)) | V4: 7000 | W4: =+U4+V4 | X4: =+W4*(1+(#REF!)/(W$37)) | Z4: =+X4+Y4 | AA4: =+Z4*(1+(#REF!)/(Z$37)) | AC4: =+AA4+AB4 | AD4: =+AC4*(1+(#REF!)/(AC$37)) | AE4: 8000 | AF4: =+AD4+AE4 | AG4: =+AF4*(1+(#REF!)/(AF$37)) | AI4: =+AG4+AH4 | AJ4: =+AI4*(1+(#REF!)/(AI$37)) | AK4: =B4+D4+G4+J4+M4+P4+S4+V4+Y4+AB4+AE4+AH4 | AL4: =-AK4+AJ4 | AM4: =Tableau44[[#This Row],[EP TOTALE]]+Tableau44[[#This Row],[INTERETS]] | AO4: 3 | AP4: BISSAI BI NOMBO Fabrice | AQ4: 213000 | AR4: 31852.673 | AS4: 244852.67
A5: BOMBA FOUDA Mathieu | B5: 94000 | C5: =B5*(1+(#REF!)/(B$37)) | E5: =+D5+C5 | F5: =+E5*(1+(#REF!)/(E$37)) | H5: =+F5+G5 | I5: =+H5*(1+(#REF!)/(H$37)) | K5: =+I5+J5 | L5: =+K5*(1+(#REF!)/(K$37)) | N5: =+L5+M5 | O5: =+N5*(1+(#REF!)/(N$37)) | Q5: =+O5+P5 | R5: =+Q5*(1+(#REF!)/(Q$37)) | T5: =+R5+S5 | U5: =+T5*(1+(#REF!)/(T$37)) | W5: =+U5+V5 | X5: =+W5*(1+(#REF!)/(W$37)) | Z5: =+X5+Y5 | AA5: =+Z5*(1+(#REF!)/(Z$37)) | AC5: =+AA5+AB5 | AD5: =+AC5*(1+(#REF!)/(AC$37)) | AE5: 8000 | AF5: =+AD5+AE5 | AG5: =+AF5*(1+(#REF!)/(AF$37)) | AI5: =+AG5+AH5 | AJ5: =+AI5*(1+(#REF!)/(AI$37)) | AK5: =B5+D5+G5+J5+M5+P5+S5+V5+Y5+AB5+AE5+AH5 | AL5: =-AK5+AJ5 | AM5: =Tableau44[[#This Row],[EP TOTALE]]+Tableau44[[#This Row],[INTERETS]] | AO5: 4 | AP5: BOMBA FOUDA Mathieu | AQ5: 102000 | AR5: 16244.385 | AS5: 118244.39
A6: EBOGO BIKOULA Gilbert | B6: 100000 | C6: =B6*(1+(#REF!)/(B$37)) | E6: =+D6+C6 | F6: =+E6*(1+(#REF!)/(E$37)) | H6: =+F6+G6 | I6: =+H6*(1+(#REF!)/(H$37)) | K6: =+I6+J6 | L6: =+K6*(1+(#REF!)/(K$37)) | N6: =+L6+M6 | O6: =+N6*(1+(#REF!)/(N$37)) | Q6: =+O6+P6 | R6: =+Q6*(1+(#REF!)/(Q$37)) | T6: =+R6+S6 | U6: =+T6*(1+(#REF!)/(T$37)) | W6: =+U6+V6 | X6: =+W6*(1+(#REF!)/(W$37)) | Z6: =+X6+Y6 | AA6: =+Z6*(1+(#REF!)/(Z$37)) | AC6: =+AA6+AB6 | AD6: =+AC6*(1+(#REF!)/(AC$37)) | AF6: =+AD6+AE6 | AG6: =+AF6*(1+(#REF!)/(AF$37)) | AI6: =+AG6+AH6 | AJ6: =+AI6*(1+(#REF!)/(AI$37)) | AK6: =B6+D6+G6+J6+M6+P6+S6+V6+Y6+AB6+AE6+AH6 | AL6: =-AK6+AJ6 | AM6: =Tableau44[[#This Row],[EP TOTALE]]+Tableau44[[#This Row],[INTERETS]] | AO6: 5 | AP6: EBOGO BIKOULA Gilbert | AQ6: 100000 | AR6: 17134.354 | AS6: 117134.35
A7: ESSALA Etienne | B7: 160000 | C7: =B7*(1+(#REF!)/(B$37)) | E7: =+D7+C7 | F7: =+E7*(1+(#REF!)/(E$37)) | H7: =+F7+G7 | I7: =+H7*(1+(#REF!)/(H$37)) | K7: =+I7+J7 | L7: =+K7*(1+(#REF!)/(K$37)) | N7: =+L7+M7 | O7: =+N7*(1+(#REF!)/(N$37)) | P7: 10000 | Q7: =+O7+P7 | R7: =+Q7*(1+(#REF!)/(Q$37)) | S7: 50000 | T7: =+R7+S7 | U7: =+T7*(1+(#REF!)/(T$37)) | V7: 35000 | W7: =+U7+V7 | X7: =+W7*(1+(#REF!)/(W$37)) | Z7: =+X7+Y7 | AA7: =+Z7*(1+(#REF!)/(Z$37)) | AB7: 50000 | AC7: =+AA7+AB7 | AD7: =+AC7*(1+(#REF!)/(AC$37)) | AF7: =+AD7+AE7 | AG7: =+AF7*(1+(#REF!)/(AF$37)) | AI7: =+AG7+AH7 | AJ7: =+AI7*(1+(#REF!)/(AI$37)) | AK7: =B7+D7+G7+J7+M7+P7+S7+V7+Y7+AB7+AE7+AH7 | AL7: =-AK7+AJ7 | AM7: =Tableau44[[#This Row],[EP TOTALE]]+Tableau44[[#This Row],[INTERETS]] | AO7: 6 | AP7: ESSALA Etienne | AQ7: 345000 | AR7: 41399.479 | AS7: 386399.48
A8: ETOA Yves | B8: 100000 | C8: =B8*(1+(#REF!)/(B$37)) | E8: =+D8+C8 | F8: =+E8*(1+(#REF!)/(E$37)) | H8: =+F8+G8 | I8: =+H8*(1+(#REF!)/(H$37)) | K8: =+I8+J8 | L8: =+K8*(1+(#REF!)/(K$37)) | M8: 50000 | N8: =+L8+M8 | O8: =+N8*(1+(#REF!)/(N$37)) | P8: 130000 | Q8: =+O8+P8 | R8: =+Q8*(1+(#REF!)/(Q$37)) | S8: 50000 | T8: =+R8+S8 | U8: =+T8*(1+(#REF!)/(T$37)) | V8: 1250000 | W8: =+U8+V8 | X8: =+W8*(1+(#REF!)/(W$37)) | Y8: 100000 | Z8: =+X8+Y8 | AA8: =+Z8*(1+(#REF!)/(Z$37)) | AB8: 100000 | AC8: =+AA8+AB8 | AD8: =+AC8*(1+(#REF!)/(AC$37)) | AE8: 150000 | AF8: =+AD8+AE8 | AG8: =+AF8*(1+(#REF!)/(AF$37)) | AI8: =+AG8+AH8 | AJ8: =+AI8*(1+(#REF!)/(AI$37)) | AK8: =B8+D8+G8+J8+M8+P8+S8+V8+Y8+AB8+AE8+AH8 | AL8: =-AK8+AJ8 | AM8: =Tableau44[[#This Row],[EP TOTALE]]+Tableau44[[#This Row],[INTERETS]] | AO8: 7 | AP8: ETOA Yves | AQ8: 3356100 | AR8: 314209.21 | AS8: 3670309.2
A9: EWALA Jacques Philippe | B9: 19000 | C9: =B9*(1+(#REF!)/(B$37)) | E9: =+D9+C9 | F9: =+E9*(1+(#REF!)/(E$37)) | H9: =+F9+G9 | I9: =+H9*(1+(#REF!)/(H$37)) | K9: =+I9+J9 | L9: =+K9*(1+(#REF!)/(K$37)) | N9: =+L9+M9 | O9: =+N9*(1+(#REF!)/(N$37)) | Q9: =+O9+P9 | R9: =+Q9*(1+(#REF!)/(Q$37)) | T9: =+R9+S9 | U9: =+T9*(1+(#REF!)/(T$37)) | W9: =+U9+V9 | X9: =+W9*(1+(#REF!)/(W$37)) | Z9: =+X9+Y9 | AA9: =+Z9*(1+(#REF!)/(Z$37)) | AB9: 0 | AC9: =+AA9+AB9 | AD9: =+AC9*(1+(#REF!)/(AC$37)) | AF9: =+AD9+AE9 | AG9: =+AF9*(1+(#REF!)/(AF$37)) | AI9: =+AG9+AH9 | AJ9: =+AI9*(1+(#REF!)/(AI$37)) | AK9: =B9+D9+G9+J9+M9+P9+S9+V9+Y9+AB9+AE9+AH9 | AL9: =-AK9+AJ9 | AM9: =Tableau44[[#This Row],[EP TOTALE]]+Tableau44[[#This Row],[INTERETS]] | AO9: 8 | AP9: EWALA Jacques Philippe | AQ9: 100000 | AR9: 16306.536 | AS9: 116306.54
A10: FOTUE KAMGUE Kevin | B10: 100000 | C10: =B10*(1+(#REF!)/(B$37)) | E10: =+D10+C10 | F10: =+E10*(1+(#REF!)/(E$37)) | H10: =+F10+G10 | I10: =+H10*(1+(#REF!)/(H$37)) | K10: =+I10+J10 | L10: =+K10*(1+(#REF!)/(K$37)) | N10: =+L10+M10 | O10: =+N10*(1+(#REF!)/(N$37)) | Q10: =+O10+P10 | R10: =+Q10*(1+(#REF!)/(Q$37)) | T10: =+R10+S10 | U10: =+T10*(1+(#REF!)/(T$37)) | W10: =+U10+V10 | X10: =+W10*(1+(#REF!)/(W$37)) | Z10: =+X10+Y10 | AA10: =+Z10*(1+(#REF!)/(Z$37)) | AC10: =+AA10+AB10 | AD10: =+AC10*(1+(#REF!)/(AC$37)) | AF10: =+AD10+AE10 | AG10: =+AF10*(1+(#REF!)/(AF$37)) | AI10: =+AG10+AH10 | AJ10: =+AI10*(1+(#REF!)/(AI$37)) | AK10: =B10+D10+G10+J10+M10+P10+S10+V10+Y10+AB10+AE10+AH10 | AL10: =-AK10+AJ10 | AM10: =Tableau44[[#This Row],[EP TOTALE]]+Tableau44[[#This Row],[INTERETS]] | AO10: 9 | AP10: FOTUE KAMGUE Kevin | AQ10: 100000 | AR10: 17134.354 | AS10: 117134.35
A11: IPOULE Michel Landry | B11: 94000 | C11: =B11*(1+(#REF!)/(B$37)) | E11: =+D11+C11 | F11: =+E11*(1+(#REF!)/(E$37)) | H11: =+F11+G11 | I11: =+H11*(1+(#REF!)/(H$37)) | K11: =+I11+J11 | L11: =+K11*(1+(#REF!)/(K$37)) | N11: =+L11+M11 | O11: =+N11*(1+(#REF!)/(N$37)) | Q11: =+O11+P11 | R11: =+Q11*(1+(#REF!)/(Q$37)) | T11: =+R11+S11 | U11: =+T11*(1+(#REF!)/(T$37)) | W11: =+U11+V11 | X11: =+W11*(1+(#REF!)/(W$37)) | Z11: =+X11+Y11 | AA11: =+Z11*(1+(#REF!)/(Z$37)) | AB11: 6000 | AC11: =+AA11+AB11 | AD11: =+AC11*(1+(#REF!)/(AC$37)) | AF11: =+AD11+AE11 | AG11: =+AF11*(1+(#REF!)/(AF$37)) | AI11: =+AG11+AH11 | AJ11: =+AI11*(1+(#REF!)/(AI$37)) | AK11: =B11+D11+G11+J11+M11+P11+S11+V11+Y11+AB11+AE11+AH11 | AL11: =-AK11+AJ11 | AM11: =Tableau44[[#This Row],[EP TOTALE]]+Tableau44[[#This Row],[INTERETS]] | AO11: 10 | AP11: IPOULE Michel Landry | AQ11: 100000 | AR11: 16315.075 | AS11: 116315.08
A12: ITOP Samuel | B12: 200000 | C12: =B12*(1+(#REF!)/(B$37)) | E12: =+D12+C12 | F12: =+E12*(1+(#REF!)/(E$37)) | H12: =+F12+G12 | I12: =+H12*(1+(#REF!)/(H$37)) | K12: =+I12+J12 | L12: =+K12*(1+(#REF!)/(K$37)) | M12: 100000 | N12: =+L12+M12 | O12: =+N12*(1+(#REF!)/(N$37)) | P12: 100000 | Q12: =+O12+P12 | R12: =+Q12*(1+(#REF!)/(Q$37)) | S12: 100000 | T12: =+R12+S12 | U12: =+T12*(1+(#REF!)/(T$37)) | V12: 100000 | W12: =+U12+V12 | X12: =+W12*(1+(#REF!)/(W$37)) | Y12: 100000 | Z12: =+X12+Y12 | AA12: =+Z12*(1+(#REF!)/(Z$37)) | AB12: 100000 | AC12: =+AA12+AB12 | AD12: =+AC12*(1+(#REF!)/(AC$37)) | AE12: 100000 | AF12: =+AD12+AE12 | AG12: =+AF12*(1+(#REF!)/(AF$37)) | AI12: =+AG12+AH12 | AJ12: =+AI12*(1+(#REF!)/(AI$37)) | AK12: =B12+D12+G12+J12+M12+P12+S12+V12+Y12+AB12+AE12+AH12 | AL12: =-AK12+AJ12 | AM12: =Tableau44[[#This Row],[EP TOTALE]]+Tableau44[[#This Row],[INTERETS]] | AO12: 11 | AP12: ITOP Samuel | AQ12: 1400000 | AR12: 150574.44 | AS12: 1550574.4
A13: LIKENG BALEBA | B13: 100000 | C13: =B13*(1+(#REF!)/(B$37)) | E13: =+D13+C13 | F13: =+E13*(1+(#REF!)/(E$37)) | H13: =+F13+G13 | I13: =+H13*(1+(#REF!)/(H$37)) | K13: =+I13+J13 | L13: =+K13*(1+(#REF!)/(K$37)) | N13: =+L13+M13 | O13: =+N13*(1+(#REF!)/(N$37)) | Q13: =+O13+P13 | R13: =+Q13*(1+(#REF!)/(Q$37)) | T13: =+R13+S13 | U13: =+T13*(1+(#REF!)/(T$37)) | V13: 5000 | W13: =+U13+V13 | X13: =+W13*(1+(#REF!)/(W$37)) | Z13: =+X13+Y13 | AA13: =+Z13*(1+(#REF!)/(Z$37)) | AC13: =+AA13+AB13 | AD13: =+AC13*(1+(#REF!)/(AC$37)) | AE13: 18000 | AF13: =+AD13+AE13 | AG13: =+AF13*(1+(#REF!)/(AF$37)) | AI13: =+AG13+AH13 | AJ13: =+AI13*(1+(#REF!)/(AI$37)) | AK13: =B13+D13+G13+J13+M13+P13+S13+V13+Y13+AB13+AE13+AH13 | AL13: =-AK13+AJ13 | AM13: =Tableau44[[#This Row],[EP TOTALE]]+Tableau44[[#This Row],[INTERETS]] | AO13: 12 | AP13: LIKENG BALEBA | AQ13: 125000 | AR13: 18024.049 | AS13: 143024.05
A14: MAMA Paul Yannick | B14: 94000 | C14: =B14*(1+(#REF!)/(B$37)) | E14: =+D14+C14 | F14: =+E14*(1+(#REF!)/(E$37)) | H14: =+F14+G14 | I14: =+H14*(1+(#REF!)/(H$37)) | K14: =+I14+J14 | L14: =+K14*(1+(#REF!)/(K$37)) | N14: =+L14+M14 | O14: =+N14*(1+(#REF!)/(N$37)) | Q14: =+O14+P14 | R14: =+Q14*(1+(#REF!)/(Q$37)) | T14: =+R14+S14 | U14: =+T14*(1+(#REF!)/(T$37)) | W14: =+U14+V14 | X14: =+W14*(1+(#REF!)/(W$37)) | Z14: =+X14+Y14 | AA14: =+Z14*(1+(#REF!)/(Z$37)) | AC14: =+AA14+AB14 | AD14: =+AC14*(1+(#REF!)/(AC$37)) | AF14: =+AD14+AE14 | AG14: =+AF14*(1+(#REF!)/(AF$37)) | AI14: =+AG14+AH14 | AJ14: =+AI14*(1+(#REF!)/(AI$37)) | AK14: =B14+D14+G14+J14+M14+P14+S14+V14+Y14+AB14+AE14+AH14 | AL14: =-AK14+AJ14 | AM14: =Tableau44[[#This Row],[EP TOTALE]]+Tableau44[[#This Row],[INTERETS]] | AO14: 13 | AP14: MAMA Paul Yannick | AQ14: 132000 | AR14: 20807.61 | AS14: 152807.61
A15: MANI EKOUDI François M. | B15: 0 | C15: =B15*(1+(#REF!)/(B$37)) | E15: =+D15+C15 | F15: =+E15*(1+(#REF!)/(E$37)) | H15: =+F15+G15 | I15: =+H15*(1+(#REF!)/(H$37)) | K15: =+I15+J15 | L15: =+K15*(1+(#REF!)/(K$37)) | M15: 100000 | N15: =+L15+M15 | O15: =+N15*(1+(#REF!)/(N$37)) | Q15: =+O15+P15 | R15: =+Q15*(1+(#REF!)/(Q$37)) | T15: =+R15+S15 | U15: =+T15*(1+(#REF!)/(T$37)) | W15: =+U15+V15 | X15: =+W15*(1+(#REF!)/(W$37)) | Z15: =+X15+Y15 | AA15: =+Z15*(1+(#REF!)/(Z$37)) | AC15: =+AA15+AB15 | AD15: =+AC15*(1+(#REF!)/(AC$37)) | AF15: =+AD15+AE15 | AG15: =+AF15*(1+(#REF!)/(AF$37)) | AI15: =+AG15+AH15 | AJ15: =+AI15*(1+(#REF!)/(AI$37)) | AK15: =B15+D15+G15+J15+M15+P15+S15+V15+Y15+AB15+AE15+AH15 | AL15: =-AK15+AJ15 | AM15: =Tableau44[[#This Row],[EP TOTALE]]+Tableau44[[#This Row],[INTERETS]] | AO15: 14 | AP15: MANI EKOUDI François M. | AQ15: 180000 | AR15: 21542.542 | AS15: 201542.54
A16: MBA ENYOUGOU Bernard | B16: 52000 | C16: =B16*(1+(#REF!)/(B$37)) | E16: =+D16+C16 | F16: =+E16*(1+(#REF!)/(E$37)) | H16: =+F16+G16 | I16: =+H16*(1+(#REF!)/(H$37)) | K16: =+I16+J16 | L16: =+K16*(1+(#REF!)/(K$37)) | N16: =+L16+M16 | O16: =+N16*(1+(#REF!)/(N$37)) | Q16: =+O16+P16 | R16: =+Q16*(1+(#REF!)/(Q$37)) | T16: =+R16+S16 | U16: =+T16*(1+(#REF!)/(T$37)) | W16: =+U16+V16 | X16: =+W16*(1+(#REF!)/(W$37)) | Z16: =+X16+Y16 | AA16: =+Z16*(1+(#REF!)/(Z$37)) | AB16: 7000 | AC16: =+AA16+AB16 | AD16: =+AC16*(1+(#REF!)/(AC$37)) | AF16: =+AD16+AE16 | AG16: =+AF16*(1+(#REF!)/(AF$37)) | AI16: =+AG16+AH16 | AJ16: =+AI16*(1+(#REF!)/(AI$37)) | AK16: =B16+D16+G16+J16+M16+P16+S16+V16+Y16+AB16+AE16+AH16 | AL16: =-AK16+AJ16 | AM16: =Tableau44[[#This Row],[EP TOTALE]]+Tableau44[[#This Row],[INTERETS]] | AO16: 15 | AP16: MBA ENYOUGOU Bernard | AQ16: 89000 | AR16: 13386.458 | AS16: 102386.46
A17: MBADI Homer Paul | B17: 33000 | C17: =B17*(1+(#REF!)/(B$37)) | E17: =+D17+C17 | F17: =+E17*(1+(#REF!)/(E$37)) | H17: =+F17+G17 | I17: =+H17*(1+(#REF!)/(H$37)) | K17: =+I17+J17 | L17: =+K17*(1+(#REF!)/(K$37)) | M17: 500000 | N17: =+L17+M17 | O17: =+N17*(1+(#REF!)/(N$37)) | P17: 500000 | Q17: =+O17+P17 | R17: =+Q17*(1+(#REF!)/(Q$37)) | S17: 500000 | T17: =+R17+S17 | U17: =+T17*(1+(#REF!)/(T$37)) | V17: 500000 | W17: =+U17+V17 | X17: =+W17*(1+(#REF!)/(W$37)) | Y17: 500000 | Z17: =+X17+Y17 | AA17: =+Z17*(1+(#REF!)/(Z$37)) | AB17: 500000 | AC17: =+AA17+AB17 | AD17: =+AC17*(1+(#REF!)/(AC$37)) | AE17: 500000 | AF17: =+AD17+AE17 | AG17: =+AF17*(1+(#REF!)/(AF$37)) | AI17: =+AG17+AH17 | AJ17: =+AI17*(1+(#REF!)/(AI$37)) | AK17: =B17+D17+G17+J17+M17+P17+S17+V17+Y17+AB17+AE17+AH17 | AL17: =-AK17+AJ17 | AM17: =Tableau44[[#This Row],[EP TOTALE]]+Tableau44[[#This Row],[INTERETS]] | AO17: 16 | AP17: MBADI Homer Paul | AQ17: 5033000 | AR17: 469130.29 | AS17: 5502130.3
A18: MBAMBA NSOA Jean Paul | B18: 200000 | C18: =B18*(1+(#REF!)/(B$37)) | E18: =+D18+C18 | F18: =+E18*(1+(#REF!)/(E$37)) | H18: =+F18+G18 | I18: =+H18*(1+(#REF!)/(H$37)) | K18: =+I18+J18 | L18: =+K18*(1+(#REF!)/(K$37)) | M18: 100000 | N18: =+L18+M18 | O18: =+N18*(1+(#REF!)/(N$37)) | Q18: =+O18+P18 | R18: =+Q18*(1+(#REF!)/(Q$37)) | S18: 100000 | T18: =+R18+S18 | U18: =+T18*(1+(#REF!)/(T$37)) | W18: =+U18+V18 | X18: =+W18*(1+(#REF!)/(W$37)) | Z18: =+X18+Y18 | AA18: =+Z18*(1+(#REF!)/(Z$37)) | AC18: =+AA18+AB18 | AD18: =+AC18*(1+(#REF!)/(AC$37)) | AE18: 18000 | AF18: =+AD18+AE18 | AG18: =+AF18*(1+(#REF!)/(AF$37)) | AI18: =+AG18+AH18 | AJ18: =+AI18*(1+(#REF!)/(AI$37)) | AK18: =B18+D18+G18+J18+M18+P18+S18+V18+Y18+AB18+AE18+AH18 | AL18: =-AK18+AJ18 | AM18: =Tableau44[[#This Row],[EP TOTALE]]+Tableau44[[#This Row],[INTERETS]] | AO18: 17 | AP18: MBAMBA NSOA Jean Paul | AQ18: 518000 | AR18: 69497.893 | AS18: 587497.89
A19: MENGUE François Xavier | B19: 40000 | C19: =B19*(1+(#REF!)/(B$37)) | E19: =+D19+C19 | F19: =+E19*(1+(#REF!)/(E$37)) | H19: =+F19+G19 | I19: =+H19*(1+(#REF!)/(H$37)) | K19: =+I19+J19 | L19: =+K19*(1+(#REF!)/(K$37)) | N19: =+L19+M19 | O19: =+N19*(1+(#REF!)/(N$37)) | P19: 88000 | Q19: =+O19+P19 | R19: =+Q19*(1+(#REF!)/(Q$37)) | T19: =+R19+S19 | U19: =+T19*(1+(#REF!)/(T$37)) | W19: =+U19+V19 | X19: =+W19*(1+(#REF!)/(W$37)) | Z19: =+X19+Y19 | AA19: =+Z19*(1+(#REF!)/(Z$37)) | AC19: =+AA19+AB19 | AD19: =+AC19*(1+(#REF!)/(AC$37)) | AF19: =+AD19+AE19 | AG19: =+AF19*(1+(#REF!)/(AF$37)) | AI19: =+AG19+AH19 | AJ19: =+AI19*(1+(#REF!)/(AI$37)) | AK19: =B19+D19+G19+J19+M19+P19+S19+V19+Y19+AB19+AE19+AH19 | AL19: =-AK19+AJ19 | AM19: =Tableau44[[#This Row],[EP TOTALE]]+Tableau44[[#This Row],[INTERETS]] | AO19: 18 | AP19: MENGUE François Xavier | AQ19: 128000 | AR19: 15185.255 | AS19: 143185.26
A20: MIONG RIGOBERT Dieudonné | B20: 100000 | C20: =B20*(1+(#REF!)/(B$37)) | E20: =+D20+C20 | F20: =+E20*(1+(#REF!)/(E$37)) | H20: =+F20+G20 | I20: =+H20*(1+(#REF!)/(H$37)) | K20: =+I20+J20 | L20: =+K20*(1+(#REF!)/(K$37)) | N20: =+L20+M20 | O20: =+N20*(1+(#REF!)/(N$37)) | Q20: =+O20+P20 | R20: =+Q20*(1+(#REF!)/(Q$37)) | T20: =+R20+S20 | U20: =+T20*(1+(#REF!)/(T$37)) | W20: =+U20+V20 | X20: =+W20*(1+(#REF!)/(W$37)) | Z20: =+X20+Y20 | AA20: =+Z20*(1+(#REF!)/(Z$37)) | AC20: =+AA20+AB20 | AD20: =+AC20*(1+(#REF!)/(AC$37)) | AF20: =+AD20+AE20 | AG20: =+AF20*(1+(#REF!)/(AF$37)) | AI20: =+AG20+AH20 | AJ20: =+AI20*(1+(#REF!)/(AI$37)) | AK20: =B20+D20+G20+J20+M20+P20+S20+V20+Y20+AB20+AE20+AH20 | AL20: =-AK20+AJ20 | AM20: =Tableau44[[#This Row],[EP TOTALE]]+Tableau44[[#This Row],[INTERETS]] | AO20: 19 | AP20: MIONG RIGOBERT Dieudonné | AQ20: 120000 | AR20: 19608.731 | AS20: 139608.73
A21: NDJOCK Thaddée Rodrigue | B21: 0 | C21: =B21*(1+(#REF!)/(B$37)) | E21: =+D21+C21 | F21: =+E21*(1+(#REF!)/(E$37)) | H21: =+F21+G21 | I21: =+H21*(1+(#REF!)/(H$37)) | K21: =+I21+J21 | L21: =+K21*(1+(#REF!)/(K$37)) | N21: =+L21+M21 | O21: =+N21*(1+(#REF!)/(N$37)) | Q21: =+O21+P21 | R21: =+Q21*(1+(#REF!)/(Q$37)) | T21: =+R21+S21 | U21: =+T21*(1+(#REF!)/(T$37)) | W21: =+U21+V21 | X21: =+W21*(1+(#REF!)/(W$37)) | Z21: =+X21+Y21 | AA21: =+Z21*(1+(#REF!)/(Z$37)) | AC21: =+AA21+AB21 | AD21: =+AC21*(1+(#REF!)/(AC$37)) | AF21: =+AD21+AE21 | AG21: =+AF21*(1+(#REF!)/(AF$37)) | AI21: =+AG21+AH21 | AJ21: =+AI21*(1+(#REF!)/(AI$37)) | AK21: =B21+D21+G21+J21+M21+P21+S21+V21+Y21+AB21+AE21+AH21 | AL21: =-AK21+AJ21 | AM21: =Tableau44[[#This Row],[EP TOTALE]]+Tableau44[[#This Row],[INTERETS]] | AO21: 20 | AP21: NDJOCK Thaddée Rodrigue | AQ21: 6000 | AR21: 898.74763 | AS21: 6898.7476
A22: NKOLO NGAH Emmanuel | B22: 100000 | C22: =B22*(1+(#REF!)/(B$37)) | E22: =+D22+C22 | F22: =+E22*(1+(#REF!)/(E$37)) | H22: =+F22+G22 | I22: =+H22*(1+(#REF!)/(H$37)) | K22: =+I22+J22 | L22: =+K22*(1+(#REF!)/(K$37)) | N22: =+L22+M22 | O22: =+N22*(1+(#REF!)/(N$37)) | Q22: =+O22+P22 | R22: =+Q22*(1+(#REF!)/(Q$37)) | T22: =+R22+S22 | U22: =+T22*(1+(#REF!)/(T$37)) | W22: =+U22+V22 | X22: =+W22*(1+(#REF!)/(W$37)) | Z22: =+X22+Y22 | AA22: =+Z22*(1+(#REF!)/(Z$37)) | AC22: =+AA22+AB22 | AD22: =+AC22*(1+(#REF!)/(AC$37)) | AE22: 8000 | AF22: =+AD22+AE22 | AG22: =+AF22*(1+(#REF!)/(AF$37)) | AI22: =+AG22+AH22 | AJ22: =+AI22*(1+(#REF!)/(AI$37)) | AK22: =B22+D22+G22+J22+M22+P22+S22+V22+Y22+AB22+AE22+AH22 | AL22: =-AK22+AJ22 | AM22: =Tableau44[[#This Row],[EP TOTALE]]+Tableau44[[#This Row],[INTERETS]] | AO22: 21 | AP22: NKOLO NGAH Emmanuel | AQ22: 108000 | AR22: 17272.446 | AS22: 125272.45
A23: NOAH Patrick Michel Brice | C23: =B23*(1+(#REF!)/(B$37)) | E23: =+D23+C23 | F23: =+E23*(1+(#REF!)/(E$37)) | H23: =+F23+G23 | I23: =+H23*(1+(#REF!)/(H$37)) | K23: =+I23+J23 | L23: =+K23*(1+(#REF!)/(K$37)) | M23: 100000 | N23: =+L23+M23 | O23: =+N23*(1+(#REF!)/(N$37)) | Q23: =+O23+P23 | R23: =+Q23*(1+(#REF!)/(Q$37)) | T23: =+R23+S23 | U23: =+T23*(1+(#REF!)/(T$37)) | W23: =+U23+V23 | X23: =+W23*(1+(#REF!)/(W$37)) | Z23: =+X23+Y23 | AA23: =+Z23*(1+(#REF!)/(Z$37)) | AC23: =+AA23+AB23 | AD23: =+AC23*(1+(#REF!)/(AC$37)) | AF23: =+AD23+AE23 | AG23: =+AF23*(1+(#REF!)/(AF$37)) | AI23: =+AG23+AH23 | AJ23: =+AI23*(1+(#REF!)/(AI$37)) | AK23: =B23+D23+G23+J23+M23+P23+S23+V23+Y23+AB23+AE23+AH23 | AL23: =-AK23+AJ23 | AM23: =Tableau44[[#This Row],[EP TOTALE]]+Tableau44[[#This Row],[INTERETS]] | AO23: 22 | AP23: NOAH Patrick Michel Brice | AQ23: 200000 | AR23: 25728.664 | AS23: 225728.66
A24: NONBO Marc | B24: 0 | C24: =B24*(1+(#REF!)/(B$37)) | E24: =+D24+C24 | F24: =+E24*(1+(#REF!)/(E$37)) | H24: =+F24+G24 | I24: =+H24*(1+(#REF!)/(H$37)) | K24: =+I24+J24 | L24: =+K24*(1+(#REF!)/(K$37)) | N24: =+L24+M24 | O24: =+N24*(1+(#REF!)/(N$37)) | Q24: =+O24+P24 | R24: =+Q24*(1+(#REF!)/(Q$37)) | T24: =+R24+S24 | U24: =+T24*(1+(#REF!)/(T$37)) | W24: =+U24+V24 | X24: =+W24*(1+(#REF!)/(W$37)) | Y24: 100000 | Z24: =+X24+Y24 | AA24: =+Z24*(1+(#REF!)/(Z$37)) | AC24: =+AA24+AB24 | AD24: =+AC24*(1+(#REF!)/(AC$37)) | AF24: =+AD24+AE24 | AG24: =+AF24*(1+(#REF!)/(AF$37)) | AI24: =+AG24+AH24 | AJ24: =+AI24*(1+(#REF!)/(AI$37)) | AK24: =B24+D24+G24+J24+M24+P24+S24+V24+Y24+AB24+AE24+AH24 | AL24: =-AK24+AJ24 | AM24: =Tableau44[[#This Row],[EP TOTALE]]+Tableau44[[#This Row],[INTERETS]] | AO24: 23 | AP24: NONBO Marc | AQ24: 100000 | AR24: 5380.7396 | AS24: 105380.74
A25: NSOA MBONDO Pierre | B25: 100500 | C25: =B25*(1+(#REF!)/(B$37)) | E25: =+D25+C25 | F25: =+E25*(1+(#REF!)/(E$37)) | H25: =+F25+G25 | I25: =+H25*(1+(#REF!)/(H$37)) | K25: =+I25+J25 | L25: =+K25*(1+(#REF!)/(K$37)) | N25: =+L25+M25 | O25: =+N25*(1+(#REF!)/(N$37)) | Q25: =+O25+P25 | R25: =+Q25*(1+(#REF!)/(Q$37)) | T25: =+R25+S25 | U25: =+T25*(1+(#REF!)/(T$37)) | W25: =+U25+V25 | X25: =+W25*(1+(#REF!)/(W$37)) | Z25: =+X25+Y25 | AA25: =+Z25*(1+(#REF!)/(Z$37)) | AC25: =+AA25+AB25 | AD25: =+AC25*(1+(#REF!)/(AC$37)) | AF25: =+AD25+AE25 | AG25: =+AF25*(1+(#REF!)/(AF$37)) | AI25: =+AG25+AH25 | AJ25: =+AI25*(1+(#REF!)/(AI$37)) | AK25: =B25+D25+G25+J25+M25+P25+S25+V25+Y25+AB25+AE25+AH25 | AL25: =-AK25+AJ25 | AM25: =Tableau44[[#This Row],[EP TOTALE]]+Tableau44[[#This Row],[INTERETS]] | AO25: 24 | AP25: NSOA MBONDO Pierre | AQ25: 100500 | AR25: 17220.025 | AS25: 117720.03
A26: NSOE NKOULI Jean-Baptiste | B26: 100000 | C26: =B26*(1+(#REF!)/(B$37)) | E26: =+D26+C26 | F26: =+E26*(1+(#REF!)/(E$37)) | H26: =+F26+G26 | I26: =+H26*(1+(#REF!)/(H$37)) | K26: =+I26+J26 | L26: =+K26*(1+(#REF!)/(K$37)) | N26: =+L26+M26 | O26: =+N26*(1+(#REF!)/(N$37)) | Q26: =+O26+P26 | R26: =+Q26*(1+(#REF!)/(Q$37)) | T26: =+R26+S26 | U26: =+T26*(1+(#REF!)/(T$37)) | W26: =+U26+V26 | X26: =+W26*(1+(#REF!)/(W$37)) | Y26: 0 | Z26: =+X26+Y26 | AA26: =+Z26*(1+(#REF!)/(Z$37)) | AC26: =+AA26+AB26 | AD26: =+AC26*(1+(#REF!)/(AC$37)) | AE26: 150000 | AF26: =+AD26+AE26 | AG26: =+AF26*(1+(#REF!)/(AF$37)) | AI26: =+AG26+AH26 | AJ26: =+AI26*(1+(#REF!)/(AI$37)) | AK26: =B26+D26+G26+J26+M26+P26+S26+V26+Y26+AB26+AE26+AH26 | AL26: =-AK26+AJ26 | AM26: =Tableau44[[#This Row],[EP TOTALE]]+Tableau44[[#This Row],[INTERETS]] | AO26: 25 | AP26: NSOE NKOULI Jean-Baptiste | AQ26: 250000 | AR26: 19723.592 | AS26: 269723.59
A27: NYECK PONDI Etienne | B27: 600000 | C27: =B27*(1+(#REF!)/(B$37)) | E27: =+D27+C27 | F27: =+E27*(1+(#REF!)/(E$37)) | H27: =+F27+G27 | I27: =+H27*(1+(#REF!)/(H$37)) | K27: =+I27+J27 | L27: =+K27*(1+(#REF!)/(K$37)) | M27: 150000 | N27: =+L27+M27 | O27: =+N27*(1+(#REF!)/(N$37)) | Q27: =+O27+P27 | R27: =+Q27*(1+(#REF!)/(Q$37)) | T27: =+R27+S27 | U27: =+T27*(1+(#REF!)/(T$37)) | W27: =+U27+V27 | X27: =+W27*(1+(#REF!)/(W$37)) | Z27: =+X27+Y27 | AA27: =+Z27*(1+(#REF!)/(Z$37)) | AC27: =+AA27+AB27 | AD27: =+AC27*(1+(#REF!)/(AC$37)) | AF27: =+AD27+AE27 | AG27: =+AF27*(1+(#REF!)/(AF$37)) | AI27: =+AG27+AH27 | AJ27: =+AI27*(1+(#REF!)/(AI$37)) | AK27: =B27+D27+G27+J27+M27+P27+S27+V27+Y27+AB27+AE27+AH27 | AL27: =-AK27+AJ27 | AM27: =Tableau44[[#This Row],[EP TOTALE]]+Tableau44[[#This Row],[INTERETS]] | AO27: 26 | AP27: NYECK PONDI Etienne | AQ27: 750000 | AR27: 118930.43 | AS27: 868930.43
A28: OMGBA FOUDA Simon Pierre | B28: 54000 | C28: =B28*(1+(#REF!)/(B$37)) | E28: =+D28+C28 | F28: =+E28*(1+(#REF!)/(E$37)) | H28: =+F28+G28 | I28: =+H28*(1+(#REF!)/(H$37)) | K28: =+I28+J28 | L28: =+K28*(1+(#REF!)/(K$37)) | N28: =+L28+M28 | O28: =+N28*(1+(#REF!)/(N$37)) | Q28: =+O28+P28 | R28: =+Q28*(1+(#REF!)/(Q$37)) | T28: =+R28+S28 | U28: =+T28*(1+(#REF!)/(T$37)) | W28: =+U28+V28 | X28: =+W28*(1+(#REF!)/(W$37)) | Y28: 100000 | Z28: =+X28+Y28 | AA28: =+Z28*(1+(#REF!)/(Z$37)) | AC28: =+AA28+AB28 | AD28: =+AC28*(1+(#REF!)/(AC$37)) | AF28: =+AD28+AE28 | AG28: =+AF28*(1+(#REF!)/(AF$37)) | AI28: =+AG28+AH28 | AJ28: =+AI28*(1+(#REF!)/(AI$37)) | AK28: =B28+D28+G28+J28+M28+P28+S28+V28+Y28+AB28+AE28+AH28 | AL28: =-AK28+AJ28 | AM28: =Tableau44[[#This Row],[EP TOTALE]]+Tableau44[[#This Row],[INTERETS]] | AO28: 27 | AP28: OMGBA FOUDA Simon Pierre | AQ28: 304000 | AR28: 38235.21 | AS28: 342235.21
A29: OMGBA MIMBOE Gaetan | B29: 300000 | C29: =B29*(1+(#REF!)/(B$37)) | E29: =+D29+C29 | F29: =+E29*(1+(#REF!)/(E$37)) | H29: =+F29+G29 | I29: =+H29*(1+(#REF!)/(H$37)) | K29: =+I29+J29 | L29: =+K29*(1+(#REF!)/(K$37)) | M29: 200000 | N29: =+L29+M29 | O29: =+N29*(1+(#REF!)/(N$37)) | P29: 50000 | Q29: =+O29+P29 | R29: =+Q29*(1+(#REF!)/(Q$37)) | T29: =+R29+S29 | U29: =+T29*(1+(#REF!)/(T$37)) | W29: =+U29+V29 | X29: =+W29*(1+(#REF!)/(W$37)) | Y29: 50000 | Z29: =+X29+Y29 | AA29: =+Z29*(1+(#REF!)/(Z$37)) | AC29: =+AA29+AB29 | AD29: =+AC29*(1+(#REF!)/(AC$37)) | AF29: =+AD29+AE29 | AG29: =+AF29*(1+(#REF!)/(AF$37)) | AI29: =+AG29+AH29 | AJ29: =+AI29*(1+(#REF!)/(AI$37)) | AK29: =B29+D29+G29+J29+M29+P29+S29+V29+Y29+AB29+AE29+AH29 | AL29: =-AK29+AJ29 | AM29: =Tableau44[[#This Row],[EP TOTALE]]+Tableau44[[#This Row],[INTERETS]] | AO29: 28 | AP29: OMGBA MIMBOE Gaetan | AQ29: 747000 | AR29: 100383.23 | AS29: 847383.23
A30: ONANA NKADA Laurent S. | B30: 106000 | C30: =B30*(1+(#REF!)/(B$37)) | E30: =+D30+C30 | F30: =+E30*(1+(#REF!)/(E$37)) | H30: =+F30+G30 | I30: =+H30*(1+(#REF!)/(H$37)) | K30: =+I30+J30 | L30: =+K30*(1+(#REF!)/(K$37)) | N30: =+L30+M30 | O30: =+N30*(1+(#REF!)/(N$37)) | Q30: =+O30+P30 | R30: =+Q30*(1+(#REF!)/(Q$37)) | T30: =+R30+S30 | U30: =+T30*(1+(#REF!)/(T$37)) | W30: =+U30+V30 | X30: =+W30*(1+(#REF!)/(W$37)) | Y30: 5000 | Z30: =+X30+Y30 | AA30: =+Z30*(1+(#REF!)/(Z$37)) | AC30: =+AA30+AB30 | AD30: =+AC30*(1+(#REF!)/(AC$37)) | AF30: =+AD30+AE30 | AG30: =+AF30*(1+(#REF!)/(AF$37)) | AI30: =+AG30+AH30 | AJ30: =+AI30*(1+(#REF!)/(AI$37)) | AK30: =B30+D30+G30+J30+M30+P30+S30+V30+Y30+AB30+AE30+AH30 | AL30: =-AK30+AJ30 | AM30: =Tableau44[[#This Row],[EP TOTALE]]+Tableau44[[#This Row],[INTERETS]] | AO30: 29 | AP30: ONANA NKADA Laurent S. | AQ30: 111000 | AR30: 18431.452 | AS30: 129431.45
A31: ONDOA Jean | B31: 94000 | C31: =B31*(1+(#REF!)/(B$37)) | E31: =+D31+C31 | F31: =+E31*(1+(#REF!)/(E$37)) | H31: =+F31+G31 | I31: =+H31*(1+(#REF!)/(H$37)) | K31: =+I31+J31 | L31: =+K31*(1+(#REF!)/(K$37)) | N31: =+L31+M31 | O31: =+N31*(1+(#REF!)/(N$37)) | P31: 88000 | Q31: =+O31+P31 | R31: =+Q31*(1+(#REF!)/(Q$37)) | T31: =+R31+S31 | U31: =+T31*(1+(#REF!)/(T$37)) | W31: =+U31+V31 | X31: =+W31*(1+(#REF!)/(W$37)) | Z31: =+X31+Y31 | AA31: =+Z31*(1+(#REF!)/(Z$37)) | AC31: =+AA31+AB31 | AD31: =+AC31*(1+(#REF!)/(AC$37)) | AF31: =+AD31+AE31 | AG31: =+AF31*(1+(#REF!)/(AF$37)) | AI31: =+AG31+AH31 | AJ31: =+AI31*(1+(#REF!)/(AI$37)) | AK31: =B31+D31+G31+J31+M31+P31+S31+V31+Y31+AB31+AE31+AH31 | AL31: =-AK31+AJ31 | AM31: =Tableau44[[#This Row],[EP TOTALE]]+Tableau44[[#This Row],[INTERETS]] | AO31: 30 | AP31: ONDOA Jean | AQ31: 182000 | AR31: 24437.806 | AS31: 206437.81
A32: TSANGA TSANGA Christol | B32: 32800 | C32: =B32*(1+(#REF!)/(B$37)) | E32: =+D32+C32 | F32: =+E32*(1+(#REF!)/(E$37)) | H32: =+F32+G32 | I32: =+H32*(1+(#REF!)/(H$37)) | K32: =+I32+J32 | L32: =+K32*(1+(#REF!)/(K$37)) | N32: =+L32+M32 | O32: =+N32*(1+(#REF!)/(N$37)) | Q32: =+O32+P32 | R32: =+Q32*(1+(#REF!)/(Q$37)) | S32: 100000 | T32: =+R32+S32 | U32: =+T32*(1+(#REF!)/(T$37)) | W32: =+U32+V32 | X32: =+W32*(1+(#REF!)/(W$37)) | Z32: =+X32+Y32 | AA32: =+Z32*(1+(#REF!)/(Z$37)) | AC32: =+AA32+AB32 | AD32: =+AC32*(1+(#REF!)/(AC$37)) | AE32: 2000 | AF32: =+AD32+AE32 | AG32: =+AF32*(1+(#REF!)/(AF$37)) | AI32: =+AG32+AH32 | AJ32: =+AI32*(1+(#REF!)/(AI$37)) | AK32: =B32+D32+G32+J32+M32+P32+S32+V32+Y32+AB32+AE32+AH32 | AL32: =-AK32+AJ32 | AM32: =Tableau44[[#This Row],[EP TOTALE]]+Tableau44[[#This Row],[INTERETS]] | AO32: 31 | AP32: TSANGA TSANGA Christol | AQ32: 134800 | AR32: 13711.175 | AS32: 148511.18
A33: ZE ANDJE Eric | B33: 104000 | C33: =B33*(1+(#REF!)/(B$37)) | E33: =+D33+C33 | F33: =+E33*(1+(#REF!)/(E$37)) | H33: =+F33+G33 | I33: =+H33*(1+(#REF!)/(H$37)) | K33: =+I33+J33 | L33: =+K33*(1+(#REF!)/(K$37)) | M33: 100000 | N33: =+L33+M33 | O33: =+N33*(1+(#REF!)/(N$37)) | Q33: =+O33+P33 | R33: =+Q33*(1+(#REF!)/(Q$37)) | T33: =+R33+S33 | U33: =+T33*(1+(#REF!)/(T$37)) | W33: =+U33+V33 | X33: =+W33*(1+(#REF!)/(W$37)) | Z33: =+X33+Y33 | AA33: =+Z33*(1+(#REF!)/(Z$37)) | AC33: =+AA33+AB33 | AD33: =+AC33*(1+(#REF!)/(AC$37)) | AF33: =+AD33+AE33 | AG33: =+AF33*(1+(#REF!)/(AF$37)) | AI33: =+AG33+AH33 | AJ33: =+AI33*(1+(#REF!)/(AI$37)) | AK33: =B33+D33+G33+J33+M33+P33+S33+V33+Y33+AB33+AE33+AH33 | AL33: =-AK33+AJ33 | AM33: =Tableau44[[#This Row],[EP TOTALE]]+Tableau44[[#This Row],[INTERETS]] | AO33: 32 | AP33: ZE ANDJE Eric | AQ33: 344000 | AR33: 45889.907 | AS33: 389889.91
A34: SECOURS / CAYA | B34: 500000 | C34: =B34*(1+(#REF!)/(B$37)) | E34: =+D34+C34 | F34: =+E34*(1+(#REF!)/(E$37)) | H34: =+F34+G34 | I34: =+H34*(1+(#REF!)/(H$37)) | K34: =+I34+J34 | L34: =+K34*(1+(#REF!)/(K$37)) | N34: =+L34+M34 | O34: =+N34*(1+(#REF!)/(N$37)) | Q34: =+O34+P34 | R34: =+Q34*(1+(#REF!)/(Q$37)) | T34: =+R34+S34 | U34: =+T34*(1+(#REF!)/(T$37)) | W34: =+U34+V34 | X34: =+W34*(1+(#REF!)/(W$37)) | Z34: =+X34+Y34 | AA34: =+Z34*(1+(#REF!)/(Z$37)) | AC34: =+AA34+AB34 | AD34: =+AC34*(1+(#REF!)/(AC$37)) | AF34: =+AD34+AE34 | AG34: =+AF34*(1+(#REF!)/(AF$37)) | AI34: =+AG34+AH34 | AJ34: =+AI34*(1+(#REF!)/(AI$37)) | AK34: =B34+D34+G34+J34+M34+P34+S34+V34+Y34+AB34+AE34+AH34 | AL34: =-AK34+AJ34 | AM34: =Tableau44[[#This Row],[EP TOTALE]]+Tableau44[[#This Row],[INTERETS]] | AO34: 33 | AP34: SECOURS / CAYA | AQ34: 500000 | AR34: 85671.768 | AS34: 585671.77
A35: BUREAU | B35: 410000 | C35: =B35*(1+(#REF!)/(B$37)) | E35: =+D35+C35 | F35: =+E35*(1+(#REF!)/(E$37)) | H35: =+F35+G35 | I35: =+H35*(1+(#REF!)/(H$37)) | K35: =+I35+J35 | L35: =+K35*(1+(#REF!)/(K$37)) | N35: =+L35+M35 | O35: =+N35*(1+(#REF!)/(N$37)) | Q35: =+O35+P35 | R35: =+Q35*(1+(#REF!)/(Q$37)) | T35: =+R35+S35 | U35: =+T35*(1+(#REF!)/(T$37)) | W35: =+U35+V35 | X35: =+W35*(1+(#REF!)/(W$37)) | Z35: =+X35+Y35 | AA35: =+Z35*(1+(#REF!)/(Z$37)) | AC35: =+AA35+AB35 | AD35: =+AC35*(1+(#REF!)/(AC$37)) | AF35: =+AD35+AE35 | AG35: =+AF35*(1+(#REF!)/(AF$37)) | AI35: =+AG35+AH35 | AJ35: =+AI35*(1+(#REF!)/(AI$37)) | AK35: =B35+D35+G35+J35+M35+P35+S35+V35+Y35+AB35+AE35+AH35 | AL35: =-AK35+AJ35 | AM35: =Tableau44[[#This Row],[EP TOTALE]]+Tableau44[[#This Row],[INTERETS]] | AO35: 34 | AP35: BUREAU | AQ35: 410000 | AR35: 70250.85 | AS35: 480250.85
A36: AUTRES / FETE | C36: =B36*(1+(#REF!)/(B$37)) | E36: =+D36+C36 | F36: =+E36*(1+(#REF!)/(E$37)) | H36: =+F36+G36 | I36: =+H36*(1+(#REF!)/(H$37)) | K36: =+I36+J36 | L36: =+K36*(1+(#REF!)/(K$37)) | N36: =+L36+M36 | O36: =+N36*(1+(#REF!)/(N$37)) | Q36: =+O36+P36 | R36: =+Q36*(1+(#REF!)/(Q$37)) | T36: =+R36+S36 | U36: =+T36*(1+(#REF!)/(T$37)) | W36: =+U36+V36 | X36: =+W36*(1+(#REF!)/(W$37)) | Z36: =+X36+Y36 | AA36: =+Z36*(1+(#REF!)/(Z$37)) | AC36: =+AA36+AB36 | AD36: =+AC36*(1+(#REF!)/(AC$37)) | AF36: =+AD36+AE36 | AG36: =+AF36*(1+(#REF!)/(AF$37)) | AI36: =+AG36+AH36 | AJ36: =+AI36*(1+(#REF!)/(AI$37)) | AK36: =B36+D36+G36+J36+M36+P36+S36+V36+Y36+AB36+AE36+AH36 | AL36: =-AK36+AJ36 | AM36: =Tableau44[[#This Row],[EP TOTALE]]+Tableau44[[#This Row],[INTERETS]] | AO36: 35 | AP36: AUTRES / FETE | AQ36: 0 | AR36: 0 | AS36: 0
A37: total | B37: =SUM(B2:B36) | C37: =B37*(1+(#REF!)/(B$37)) | D37: =SUM(D2:D36) | E37: =+D37+C37 | F37: =+E37*(1+(#REF!)/(E$37)) | G37: =+SUM(G2:G36) | H37: =+F37+G37 | I37: =+H37*(1+(#REF!)/(H$37)) | J37: =SUM(J2:J36) | K37: =+I37+J37 | L37: =+K37*(1+(#REF!)/(K$37)) | M37: =SUM(M2:M36) | N37: =+L37+M37 | O37: =+N37*(1+(#REF!)/(N$37)) | P37: =+SUM(P2:P36) | Q37: =+O37+P37 | R37: =+Q37*(1+(#REF!)/(Q$37)) | S37: =+SUM(S2:S36) | T37: =+R37+S37 | U37: =+T37*(1+(#REF!)/(T$37)) | V37: =+SUM(V2:V36) | W37: =+U37+V37 | X37: =+W37*(1+(#REF!)/(W$37)) | Y37: =+SUM(Y2:Y36) | Z37: =+X37+Y37 | AA37: =+Z37*(1+(#REF!)/(Z$37)) | AB37: =+SUM(AB2:AB36) | AC37: =+AA37+AB37 | AD37: =+AC37*(1+(#REF!)/(AC$37)) | AE37: =+SUM(AE2:AE35) | AF37: =+AD37+AE37 | AG37: =+AF37*(1+(#REF!)/(AF$37)) | AH37: =+SUM(AH2:AH36) | AI37: =+AG37+AH37 | AJ37: =+AI37*(1+(#REF!)/(AI$37)) | AK37: =+SUM(AK2:AK36) | AL37: =-AK37+AJ37 | AM37: =Tableau44[[#This Row],[EP TOTALE]]+Tableau44[[#This Row],[INTERETS]] | AO37: 36 | AP37: total | AQ37: 16811400 | AR37: 1936080 | AS37: 18747480
AJ38: =AJ40/AJ35
G39: 1179100 | J39: 1954000 | M39: 1407000 | P39: 973000 | S39: 907000 | V39: 1897000 | Y39: 955000 | AL39: 2386080
B40: =B44/B37
...

Sheet prets25
A1: Noms et prénoms | B1: AOUT | C1: SEPT | D1: OCT | E1: NOV | F1: DEC | G1: JANV | H1: FEV | I1: MARS | J1: AVRIL | K1: MAI | L1: JUIN | M1: JUIL | N1: TOTAL | R1: PRETS | S1: INTER | T1: REMB | U1: RESTE
A2: ABENG ZE Jean Claude | N2: =+SUM(B2:M2)
A3: BANGA NNA Israel | N3: =+SUM(B3:M3)
A4: BISSAI BI NOMBO Fabrice | N4: =+SUM(B4:M4)
A5: BOMBA FOUDA Mathieu | N5: =+SUM(B5:M5)
A6: EBOGO BIKOULA Gilbert | N6: =+SUM(B6:M6)
A7: ESSALA Etienne | N7: =+SUM(B7:M7)
A8: ETOA Yves | N8: =+SUM(B8:M8)
A9: EWALA Jacques Philippe | N9: =+SUM(B9:M9)
A10: FOTUE KAMGUE Kevin | N10: =+SUM(B10:M10)
A11: IPOULE Michel Landry | N11: =+SUM(B11:M11)
A12: ITOP Samuel | N12: =+SUM(B12:M12)
A13: LIKENG BALABA | N13: =+SUM(B13:M13)
... A33: ZE ANDJE Eric | N33: =+SUM(B33:M33)
A34: TOTAL | B34: =+SUM(B2:B33) | C34: =+SUM(C2:C33) | D34: =+SUM(D2:D33) | E34: =+SUM(E2:E33) | F34: =+SUM(F2:F33) | G34: =+SUM(G2:G33) | H34: =+SUM(H2:H33) | I34: =+SUM(I2:I33) | ... M34: =+SUM(M2:M33) | N34: =+SUM(B34:M34) | Q34: =SUM(Q2:Q33)
A36: interets | B36: =B34*0.04 | C36: =C34*0.04 | D36: =D34*0.04 | E36: =E34*0.04 | F36: =F34*0.04 | G36: =G34*0.04 | H36: =H34*0.04 | I36: =I34*0.04 | ... M36: =M34*0.04
F39: =D7*(4/100)

Sheet Rem25
A1: Noms et prénoms | B1: AOUT | C1: SEPT | D1: OCT | E1: NOV | F1: DEC | G1: JANV | H1: FEV | I1: MARS | J1: AVRIL | K1: MAI | L1: JUIN | M1: JUIL | N1: TOTAL REM
A2: ABENG ZE Jean Claude | N2: =+SUM(B2:M2)
A3: BANGA NNA Israel | N3: =+SUM(B3:M3)
A4: BISSAI BI NOMBO Fabrice | N4: =+SUM(B4:M4)
A5: BOMBA FOUDA Mathieu | N5: =+SUM(B5:M5)
A6: EBOGO BIKOULA Gilbert | N6: =+SUM(B6:M6)
A7: ESSALA Etienne | N7: =+SUM(B7:M7)
A8: ETOA Yves | N8: =+SUM(B8:M8)
A9: EWALA Jacques Philippe | N9: =+SUM(B9:M9)
A10: FOTUE KAMGUE Kevin | N10: =+SUM(B10:M10)
A11: IPOULE Michel Landry | N11: =+SUM(B11:M11)
A12: ITOP Samuel | N12: =+SUM(B12:M12)
A13: LIKENG BALABA | N13: =+SUM(B13:M13)
... A33: ZE ANDJE Eric | N33: =+SUM(B33:M33)
A34: TOTAL | B34: =+SUM(B2:B33) | C34: =+SUM(C2:C33) | D34: =+SUM(D2:D33) | E34: =+SUM(E2:E33) | F34: =+SUM(F2:F33) | G34: =+SUM(G2:G33) | H34: =+SUM(H2:H33) | I34: =+SUM(I2:I33) | ... M34: =+SUM(M2:M33) | N34: =+SUM(B34:M34)
F39: =D7*(4/100)

Sheet intérêts
A1: Noms et prénoms | B1: AOUT | C1: SEPT | D1: OCT | E1: NOV | F1: DEC | G1: JANV | H1: FEV | I1: MARS | J1: AVRIL | K1: MAI | L1: JUIN | M1: JUIL | N1: TOTAL
A2: ABENG ZE Jean Claude | B2: =(prets25!B2*(4/100)) | C2: =(prets25!C2*(4/100)) | D2: =(prets25!D2*(4/100)) | E2: =(prets25!E2*(4/100)) | F2: =(prets25!F2*(4/100)) | G2: =(prets25!G2*(4/100)) | H2: =(prets25!H2*(4/100)) | I2: =(prets25!I2*(4/100)) | ... M2: =(prets25!M2*(4/100)) | N2: =+SUM(B2:M2)
A3: BANGA NNA Israel | B3: =(prets25!B3*(4/100)) | C3: =(prets25!C3*(4/100)) | D3: =(prets25!D3*(4/100)) | E3: =(prets25!E3*(4/100)) | F3: =(prets25!F3*(4/100)) | G3: =(prets25!G3*(4/100)) | H3: =(prets25!H3*(4/100)) | I3: =(prets25!I3*(4/100)) | ... M3: =(prets25!M3*(4/100)) | N3: =+SUM(B3:M3)
A4: BISSAI BI NOMBO Fabrice | B4: =(prets25!B4*(4/100)) | C4: =(prets25!C4*(4/100)) | D4: =(prets25!D4*(4/100)) | E4: =(prets25!E4*(4/100)) | F4: =(prets25!F4*(4/100)) | G4: =(prets25!G4*(4/100)) | H4: =(prets25!H4*(4/100)) | I4: =(prets25!I4*(4/100)) | ... M4: =(prets25!M4*(4/100)) | N4: =+SUM(B4:M4)
A5: BOMBA FOUDA Mathieu | B5: =(prets25!B5*(4/100)) | C5: =(prets25!C5*(4/100)) | D5: =(prets25!D5*(4/100)) | E5: =(prets25!E5*(4/100)) | F5: =(prets25!F5*(4/100)) | G5: =(prets25!G5*(4/100)) | H5: =(prets25!H5*(4/100)) | I5: =(prets25!I5*(4/100)) | ... M5: =(prets25!M5*(4/100)) | N5: =+SUM(B5:M5)
A6: EBOGO BIKOULA Gilbert | B6: =(prets25!B6*(4/100)) | C6: =(prets25!C6*(4/100)) | D6: =(prets25!D6*(4/100)) | E6: =(prets25!E6*(4/100)) | F6: =(prets25!F6*(4/100)) | G6: =(prets25!G6*(4/100)) | H6: =(prets25!H6*(4/100)) | I6: =(prets25!I6*(4/100)) | ... M6: =(prets25!M6*(4/100)) | N6: =+SUM(B6:M6)
A7: ESSALA Etienne | B7: =(prets25!B7*(4/100)) | C7: =(prets25!C7*(4/100)) | D7: =(prets25!D7*(4/100)) | E7: =(prets25!E7*(4/100)) | F7: =(prets25!F7*(4/100)) | G7: =(prets25!G7*(4/100)) | H7: =(prets25!H7*(4/100)) | I7: =(prets25!I7*(4/100)) | ... M7: =(prets25!M7*(4/100)) | N7: =+SUM(B7:M7)
A8: ETOA Yves | B8: =(prets25!B8*(4/100)) | C8: =(prets25!C8*(4/100)) | D8: =(prets25!D8*(4/100)) | E8: =(prets25!E8*(4/100)) | F8: =(prets25!F8*(4/100)) | G8: =(prets25!G8*(4/100)) | H8: =(prets25!H8*(4/100)) | I8: =(prets25!I8*(4/100)) | ... M8: =(prets25!M8*(4/100)) | N8: =+SUM(B8:M8)
A9: EWALA Jacques Philippe | B9: =(prets25!B9*(4/100)) | C9: =(prets25!C9*(4/100)) | D9: =(prets25!D9*(4/100)) | E9: =(prets25!E9*(4/100)) | F9: =(prets25!F9*(4/100)) | G9: =(prets25!G9*(4/100)) | H9: =(prets25!H9*(4/100)) | I9: =(prets25!I9*(4/100)) | ... M9: =(prets25!M9*(4/100)) | N9: =+SUM(B9:M9)
A10: FOTUE KAMGUE Kevin | B10: =(prets25!B10*(4/100)) | C10: =(prets25!C10*(4/100)) | D10: =(prets25!D10*(4/100)) | E10: =(prets25!E10*(4/100)) | F10: =(prets25!F10*(4/100)) | G10: =(prets25!G10*(4/100)) | H10: =(prets25!H10*(4/100)) | I10: =(prets25!I10*(4/100)) | ... M10: =(prets25!M10*(4/100)) | N10: =+SUM(B10:M10)
A11: IPOULE Michel Landry | B11: =(prets25!B11*(4/100)) | C11: =(prets25!C11*(4/100)) | D11: =(prets25!D11*(4/100)) | E11: =(prets25!E11*(4/100)) | F11: =(prets25!F11*(4/100)) | G11: =(prets25!G11*(4/100)) | H11: =(prets25!H11*(4/100)) | I11: =(prets25!I11*(4/100)) | ... M11: =(prets25!M11*(4/100)) | N11: =+SUM(B11:M11)
A12: ITOP Samuel | B12: =(prets25!B12*(4/100)) | C12: =(prets25!C12*(4/100)) | D12: =(prets25!D12*(4/100)) | E12: =(prets25!E12*(4/100)) | F12: =(prets25!F12*(4/100)) | G12: =(prets25!G12*(4/100)) | H12: =(prets25!H12*(4/100)) | I12: =(prets25!I12*(4/100)) | ... M12: =(prets25!M12*(4/100)) | N12: =+SUM(B12:M12)
A13: LIKENG BALABA | B13: =(prets25!B13*(4/100)) | C13: =(prets25!C13*(4/100)) | D13: =(prets25!D13*(4/100)) | E13: =(prets25!E13*(4/100)) | F13: =(prets25!F13*(4/100)) | G13: =(prets25!G13*(4/100)) | H13: =(prets25!H13*(4/100)) | I13: =(prets25!I13*(4/100)) | ... M13: =(prets25!M13*(4/100)) | N13: =+SUM(B13:M13)
... A33: ZE ANDJE Eric | B33: =(prets25!B33*(4/100)) | C33: =(prets25!C33*(4/100)) | D33: =(prets25!D33*(4/100)) | E33: =(prets25!E33*(4/100)) | F33: =(prets25!F33*(4/100)) | G33: =(prets25!G33*(4/100)) | H33: =(prets25!H33*(4/100)) | I33: =(prets25!I33*(4/100)) | ... M33: =(prets25!M33*(4/100)) | N33: =+SUM(B33:M33)
A34: TOTAL | B34: =+SUM(B2:B33) | C34: =+SUM(C2:C33) | D34: =+SUM(D2:D33) | E34: =+SUM(E2:E33) | F34: =+SUM(F2:F33) | G34: =+SUM(G2:G33) | H34: =+SUM(H2:H33) | I34: =+SUM(I2:I33) | ... N34: =+SUM(N2:N33)

Sheet insc+sec
A1: NOMS ET PRENOMS | B1: inscriptions | C1: SEC SEPT | D1: SEC OCT | E1: SEC NOV | F1: SEC DEC | G1: SEC JANV | H1: SEC FEV | I1: SEC MAR | J1: SEC AVR | K1: SEC MAI | L1: SEC JUIN | M1: SEC JUIL | N1: SEC AOUT | O1: TOTAL
A2: ABENG ZE Jean Claude | B2: 10000 | O2: =+SUM(C2:N2)
A3: BANGA NNA Israel | B3: 10000 | O3: =+SUM(C3:N3)
A4: BISSAI BI NOMBO Fabrice | B4: 10000 | O4: =+SUM(C4:N4)
A5: BOMBA FOUDA Mathieu | B5: 10000 | O5: =+SUM(C5:N5)
A6: EBOGO BIKOULA Gilbert | B6: 10000 | O6: =+SUM(C6:N6)
A7: ESSALA Etienne | B7: 10000 | O7: =+SUM(C7:N7)
A8: ETOA Yves | B8: 10000 | O8: =+SUM(C8:N8)
A9: EWALA Jacques Philippe | B9: 10000 | O9: =+SUM(C9:N9)
A10: FOTUE KAMGUE Kevin | B10: 10000 | O10: =+SUM(C10:N10)
A11: IPOULE Michel Landry | B11: 10000 | O11: =+SUM(C11:N11)
A12: ITOP Samuel | B12: 10000 | O12: =+SUM(C12:N12)
A13: LIKENG BALABA | B13: 10000 | O13: =+SUM(C13:N13)
... A33: ZE ANDJE Eric | B33: 10000 | O33: =+SUM(C33:N33)
A34: total | B34: =+SUM(B2:B33) | C34: =+SUM(C2:C33) | D34: =+SUM(D2:D33) | E34: =+SUM(E2:E33) | F34: =+SUM(F2:F33) | G34: =+SUM(G2:G33) | H34: =+SUM(H2:H33) | I34: =+SUM(I2:I33) | ... N34: =+SUM(N2:N33) | O34: =+SUM(C34:N34)

Sheet Oct.25 (2)
A1: N | B1: NOMS ET PRENOMS | C1: INSC | D1: SECOURS | E1: TONTINE | F1: POT | G1: REM_PRET | H1: EPARGNE | I1: PRÊT | J1: Colonne1 | K1: PROJET | L1: AUTRES | M1: TOTAL
A2: 0 | B2: ABENG ZE Jean Claude | E2: 200000 | F2: 3000 | M2: =+SUM(C2:L2)
A3: 0 | B3: BANGA NNA Israel | E3: 300000 | F3: 3000 | M3: =+SUM(C3:L3)
B4: BISSAI BI NOMBO Fabrice | E4: 150000 | M4: =+SUM(C4:L4)
B5: BOMBA FOUDA Mathieu | E5: 200000 | F5: 3000 | M5: =+SUM(C5:L5)
A6: 0 | B6: EBOGO BIKOULA Gilbert | E6: 100000 | F6: 3000 | M6: =+SUM(C6:L6)
B7: ESSALA Etienne | E7: 300000 | F7: 3000 | H7: 10000 | M7: =+SUM(C7:L7)
B8: ETOA Yves | E8: 300000 | F8: 3000 | H8: 1300000 | K8: 200000 | M8: =+SUM(C8:L8)
B9: EWALA Jacques Philippe | E9: 100000 | F9: 3000 | M9: =+SUM(C9:L9)
B10: FOTUE KAMGUE Kevin | E10: 200000 | F10: 3000 | M10: =+SUM(C10:L10)
B11: IPOULE Michel Landry | E11: 200000 | M11: =+SUM(C11:L11)
B12: ITOP Samuel | E12: 300000 | F12: 3000 | M12: =+SUM(C12:L12)
B13: LIKENG BALABA | E13: 50000 | F13: 3000 | I13: 25000 | M13: =+SUM(C13:L13)
B14: LIKENG BALABA II | E14: 400000 | F14: 3000 | M14: =+SUM(C14:L14)
B15: MAMA Paul Yannick | E15: 300000 | F15: 3000 | M15: =+SUM(C15:L15)
B16: MANI EKOUDI François M. | D16: 15000 | E16: 300000 | F16: 3000 | M16: =+SUM(C16:L16)
B17: MBA ENYOUGOU Bernard | E17: 150000 | F17: 3000 | M17: =+SUM(C17:L17)
B18: MBADI Homer Paul | E18: 600000 | F18: 3000 | H18: 300000 | M18: =+SUM(C18:L18)
B19: MBAMBA NSOA Jean Paul | E19: 100000 | F19: 3000 | M19: =+SUM(C19:L19)
B20: MENGUE François Xavier | E20: 350000 | F20: 3000 | M20: =+SUM(C20:L20)
B21: MIENYE OBIA | E21: 200000 | F21: 3000 | M21: =+SUM(C21:L21)
B22: MIONG RIGOBERT Dieudonné | E22: 300000 | F22: 3000 | G22: 6000 | M22: =+SUM(C22:L22)
B23: NDJOCK Thaddée Rodrigue | E23: 300000 | F23: 3000 | M23: =+SUM(C23:L23)
A24: 0 | B24: NKOLO NGAH Emmanuel | E24: 100000 | F24: 3000 | M24: =+SUM(C24:L24)
B25: NOAH Patrick Michel Brice | D25: 15000 | E25: 200000 | F25: 3000 | H25: 400000 | M25: =+SUM(C25:L25)
B26: NONBO Marc | E26: 100000 | F26: 3000 | M26: =+SUM(C26:L26)
B27: NSOA MBONDO Pierre | E27: 300000 | F27: 3000 | M27: =+SUM(C27:L27)
B28: NSOE NKOULI Jean-Baptiste | E28: 400000 | F28: 3000 | M28: =+SUM(C28:L28)
B29: NYECK PONDI Etienne | E29: 300000 | F29: 3000 | G29: 50000 | M29: =+SUM(C29:L29)
A30: 0 | B30: OMGBA FOUDA Simon Pierre | E30: 400000 | F30: 3000 | K30: 200000 | M30: =+SUM(C30:L30)
B31: OMGBA MIMBOE Gaetan | D31: 15000 | E31: 300000 | F31: 3000 | H31: 300000 | M31: =+SUM(C31:L31)
B32: ONANA NKADA Laurent S. | E32: 100000 | F32: 3000 | G32: 4000 | H32: 3000 | I32: 100000 | M32: =+SUM(C32:L32)
B33: ONDOA Jean | E33: 300000 | F33: 3000 | M33: =+SUM(C33:L33)
A34: 0 | B34: TSANGA TSANGA Christol | E34: 100000 | F34: 3000 | M34: =+SUM(C34:L34)
A35: 0 | B35: ZE ANDJE Eric | E35: 200000 | F35: 3000 | M35: =+SUM(C35:L35)
B36: TOTAL | C36: =+SUM(C2:C35) | D36: =+SUM(D2:D35) | E36: =+SUM(E2:E35) | F36: =+SUM(F2:F35) | G36: =+SUM(G2:G35) | H36: =+SUM(H2:H35) | I36: =+SUM(I2:I35) | J36: =+SUM(J2:J35) | ... L36: =+SUM(L2:L35) | M36: =+SUM(C36:J36)
B38: Libellés | C38: RECETTES | D38: DEPENSES | E38: SOLDE
A39: 1 | B39: Inscrip | C39: =C36
A40: 2 | B40: Secours | C40: =D36
A41: 3 | B41: Tontine | C41: =E36
...
