Workbook

Sheet ep+int
A1: NOMS ET PRENOMS | B1: EP AOUT | C1: EP AOUT+INT | D1: EP SEPT | E1: CUMUL1 | F1: EP +INT1 | G1: EP OCTO | H1: CUMUL2 | I1: EP +INT2 | J1: EP NOV | K1: CUMUL3 | L1: EP +INT3 | M1: EP DEC | N1: CUMUL4 | O1: EP+INT | P1: EP JANV | Q1: CUMUL5 | R1: EP+INT4 | S1: EP FEV | T1: CUMUL6 | U1: EP+INT5 | V1: EP MARS | W1: CUMUL7 | X1: EP+INT6 | Y1: EP AVRI | Z1: CUMUL8 | AA1: EP+INT7 | AB1: EP MAI | AC1: CUMUL9 | AD1: EP+INT8 | AE1: EP JUIN | AF1: CUMUL10 | AG1: EP+INT9 | AH1: EP JUILL | AI1: CUMUL11 | AJ1: EP+INT94 | AK1: EP TOTALE | AL1: INTERETS | AM1: N A P | AN1: Colonne1
A2: ABENG ZE Jean Claude | B2: 94000 | C2: =B2*(1+38000/4317300) -> 94827.369 | E2: =+D2+C2 -> 94827.369 | F2: =E2*(1+57680/5852300) -> 95761.983 | H2: =+F2+G2 -> 95761.983 | I2: =H2*(1+168480/7089080) -> 98037.875 | K2: =+I2+J2 -> 98037.875 | L2: =K2*(1+188880/9211560) -> 100048.11 | N2: =+L2+M2 -> 100048.11 | O2: =N2*(1+229880/10807440) -> 102176.19 | Q2: =+O2+P2 -> 102176.19 | R2: =Q2*(1+258720/12010320) -> 104377.21 | T2: =+R2+S2 -> 104377.21 | U2: =T2*(1+276600/13176040) -> 106568.37 | W2: =+U2+V2 -> 106568.37 | X2: =W2*(1+281720/15349640) -> 108524.27 | Z2: =+X2+Y2 -> 108524.27 | AA2: =Z2*(1+313600/16586360) -> 110576.15 | AC2: =+AA2+AB2 -> 110576.15 | AD2: =AC2*(1+321600/17662960) -> 112589.48 | AF2: =+AD2+AE2 -> 112589.48 | AG2: =AF2*(1+333320/18946560) -> 114570.22 | AI2: =+AG2+AH2 -> 114570.22 | AJ2: =AI2*(1+1/19279881) -> 114570.23 | AK2: =B2+D2+G2+J2+M2+P2+S2+V2+Y2+AB2+AE2+AH2 -> 94000 | AL2: =-AK2+AJ2 -> 20570.228 | AM2: =Tableau4[[#This Row],[EP TOTALE]]+Tableau4[[#This Row],[INTERETS]] -> 114570.23 | AN2: =Tableau4[[#This Row],[EP TOTALE]]*AK$40 -> 0
A3: BANGA NNA Israel | B3: 129000 | C3: =B3*(1+38000/4317300) -> 130135.43 | E3: =+D3+C3 -> 130135.43 | F3: =E3*(1+57680/5852300) -> 131418.04 | G3: 100000 | H3: =+F3+G3 -> 231418.04 | I3: =H3*(1+168480/7089080) -> 236917.95 | J3: 100000 | K3: =+I3+J3 -> 336917.95 | L3: =K3*(1+188880/9211560) -> 343826.34 | N3: =+L3+M3 -> 343826.34 | O3: =N3*(1+229880/10807440) -> 351139.71 | Q3: =+O3+P3 -> 351139.71 | R3: =Q3*(1+258720/12010320) -> 358703.78 | T3: =+R3+S3 -> 358703.78 | U3: =T3*(1+276600/13176040) -> 366233.92 | W3: =+U3+V3 -> 366233.92 | X3: =W3*(1+281720/15349640) -> 372955.61 | Z3: =+X3+Y3 -> 372955.61 | AA3: =Z3*(1+313600/16586360) -> 380007.12 | AC3: =+AA3+AB3 -> 380007.12 | AD3: =AC3*(1+321600/17662960) -> 386926.13 | AF3: =+AD3+AE3 -> 386926.13 | AG3: =AF3*(1+333320/18946560) -> 393733.18 | AI3: =+AG3+AH3 -> 393733.18 | AJ3: =AI3*(1+1/19279881) -> 393733.2 | AK3: =B3+D3+G3+J3+M3+P3+S3+V3+Y3+AB3+AE3+AH3 -> 329000 | AL3: =-AK3+AJ3 -> 64733.204 | AM3: =Tableau4[[#This Row],[EP TOTALE]]+Tableau4[[#This Row],[INTERETS]] -> 393733.2 | AN3: =Tableau4[[#This Row],[EP TOTALE]]*AK$40 -> 0
A4: BISSAI BI NOMBO Fabrice | B4: 107000 | C4: =B4*(1+38000/4317300) -> 107941.79 | D4: 56000 | E4: =+D4+C4 -> 163941.79 | F4: =E4*(1+57680/5852300) -> 165557.6 | G4: 7000 | H4: =+F4+G4 -> 172557.6 | I4: =H4*(1+168480/7089080) -> 176658.62 | J4: 7000 | K4: =+I4+J4 -> 183658.62 | L4: =K4*(1+188880/9211560) -> 187424.48 | M4: 7000 | N4: =+L4+M4 -> 194424.48 | O4: =N4*(1+229880/10807440) -> 198559.99 | P4: 7000 | Q4: =+O4+P4 -> 205559.99 | R4: =Q4*(1+258720/12010320) -> 209988.06 | S4: 7000 | T4: =+R4+S4 -> 216988.06 | U4: =T4*(1+276600/13176040) -> 221543.21 | V4: 7000 | W4: =+U4+V4 -> 228543.21 | X4: =W4*(1+281720/15349640) -> 232737.79 | Z4: =+X4+Y4 -> 232737.79 | AA4: =Z4*(1+313600/16586360) -> 237138.18 | AC4: =+AA4+AB4 -> 237138.18 | AD4: =AC4*(1+321600/17662960) -> 241455.9 | AE4: 8000 | AF4: =+AD4+AE4 -> 249455.9 | AG4: =AF4*(1+333320/18946560) -> 253844.49 | AI4: =+AG4+AH4 -> 253844.49 | AJ4: =AI4*(1+1/19279881) -> 253844.5 | AK4: =B4+D4+G4+J4+M4+P4+S4+V4+Y4+AB4+AE4+AH4 -> 213000 | AL4: =-AK4+AJ4 -> 40844.5 | AM4: =Tableau4[[#This Row],[EP TOTALE]]+Tableau4[[#This Row],[INTERETS]] -> 253844.5 | AN4: =Tableau4[[#This Row],[EP TOTALE]]*AK$40 -> 0
A5: BOMBA FOUDA Mathieu | B5: 94000 | C5: =B5*(1+38000/4317300) -> 94827.369 | E5: =+D5+C5 -> 94827.369 | F5: =E5*(1+57680/5852300) -> 95761.983 | H5: =+F5+G5 -> 95761.983 | I5: =H5*(1+168480/7089080) -> 98037.875 | K5: =+I5+J5 -> 98037.875 | L5: =K5*(1+188880/9211560) -> 100048.11 | N5: =+L5+M5 -> 100048.11 | O5: =N5*(1+229880/10807440) -> 102176.19 | Q5: =+O5+P5 -> 102176.19 | R5: =Q5*(1+258720/12010320) -> 104377.21 | T5: =+R5+S5 -> 104377.21 | U5: =T5*(1+276600/13176040) -> 106568.37 | W5: =+U5+V5 -> 106568.37 | X5: =W5*(1+281720/15349640) -> 108524.27 | Z5: =+X5+Y5 -> 108524.27 | AA5: =Z5*(1+313600/16586360) -> 110576.15 | AC5: =+AA5+AB5 -> 110576.15 | AD5: =AC5*(1+321600/17662960) -> 112589.48 | AE5: 8000 | AF5: =+AD5+AE5 -> 120589.48 | AG5: =AF5*(1+333320/18946560) -> 122710.96 | AI5: =+AG5+AH5 -> 122710.96 | AJ5: =AI5*(1+1/19279881) -> 122710.97 | AK5: =B5+D5+G5+J5+M5+P5+S5+V5+Y5+AB5+AE5+AH5 -> 102000 | AL5: =-AK5+AJ5 -> 20710.97 | AM5: =Tableau4[[#This Row],[EP TOTALE]]+Tableau4[[#This Row],[INTERETS]] -> 122710.97 | AN5: =Tableau4[[#This Row],[EP TOTALE]]*AK$40 -> 0
A6: EBOGO BIKOULA Gilbert | B6: 100000 | C6: =B6*(1+38000/4317300) -> 100880.18 | E6: =+D6+C6 -> 100880.18 | F6: =E6*(1+57680/5852300) -> 101874.45 | H6: =+F6+G6 -> 101874.45 | I6: =H6*(1+168480/7089080) -> 104295.61 | K6: =+I6+J6 -> 104295.61 | L6: =K6*(1+188880/9211560) -> 106434.16 | N6: =+L6+M6 -> 106434.16 | O6: =N6*(1+229880/10807440) -> 108698.07 | Q6: =+O6+P6 -> 108698.07 | R6: =Q6*(1+258720/12010320) -> 111039.59 | T6: =+R6+S6 -> 111039.59 | U6: =T6*(1+276600/13176040) -> 113370.6 | W6: =+U6+V6 -> 113370.6 | X6: =W6*(1+281720/15349640) -> 115451.35 | Z6: =+X6+Y6 -> 115451.35 | AA6: =Z6*(1+313600/16586360) -> 117634.2 | AC6: =+AA6+AB6 -> 117634.2 | AD6: =AC6*(1+321600/17662960) -> 119776.04 | AF6: =+AD6+AE6 -> 119776.04 | AG6: =AF6*(1+333320/18946560) -> 121883.21 | AI6: =+AG6+AH6 -> 121883.21 | AJ6: =AI6*(1+1/19279881) -> 121883.22 | AK6: =B6+D6+G6+J6+M6+P6+S6+V6+Y6+AB6+AE6+AH6 -> 100000 | AL6: =-AK6+AJ6 -> 21883.221 | AM6: =Tableau4[[#This Row],[EP TOTALE]]+Tableau4[[#This Row],[INTERETS]] -> 121883.22 | AN6: =Tableau4[[#This Row],[EP TOTALE]]*AK$40 -> 0
A7: ESSALA Etienne | B7: 160000 | C7: =B7*(1+38000/4317300) -> 161408.29 | E7: =+D7+C7 -> 161408.29 | F7: =E7*(1+57680/5852300) -> 162999.12 | H7: =+F7+G7 -> 162999.12 | I7: =H7*(1+168480/7089080) -> 166872.98 | J7: 40000 | K7: =+I7+J7 -> 206872.98 | L7: =K7*(1+188880/9211560) -> 211114.84 | N7: =+L7+M7 -> 211114.84 | O7: =N7*(1+229880/10807440) -> 215605.37 | P7: 10000 | Q7: =+O7+P7 -> 225605.37 | R7: =Q7*(1+258720/12010320) -> 230465.24 | S7: 50000 | T7: =+R7+S7 -> 280465.24 | U7: =T7*(1+276600/13176040) -> 286352.95 | V7: 35000 | W7: =+U7+V7 -> 321352.95 | X7: =W7*(1+281720/15349640) -> 327250.91 | Z7: =+X7+Y7 -> 327250.91 | AA7: =Z7*(1+313600/16586360) -> 333438.27 | AB7: 50000 | AC7: =+AA7+AB7 -> 383438.27 | AD7: =AC7*(1+321600/17662960) -> 390419.76 | AF7: =+AD7+AE7 -> 390419.76 | AG7: =AF7*(1+333320/18946560) -> 397288.27 | AI7: =+AG7+AH7 -> 397288.27 | AJ7: =AI7*(1+1/19279881) -> 397288.3 | AK7: =B7+D7+G7+J7+M7+P7+S7+V7+Y7+AB7+AE7+AH7 -> 345000 | AL7: =-AK7+AJ7 -> 52288.295 | AM7: =Tableau4[[#This Row],[EP TOTALE]]+Tableau4[[#This Row],[INTERETS]] -> 397288.3 | AN7: =Tableau4[[#This Row],[EP TOTALE]]*AK$40 -> 0
A8: ETOA Yves | B8: 100000 | C8: =B8*(1+38000/4317300) -> 100880.18 | E8: =+D8+C8 -> 100880.18 | F8: =E8*(1+57680/5852300) -> 101874.45 | G8: 176100 | H8: =+F8+G8 -> 277974.45 | I8: =H8*(1+168480/7089080) -> 284580.83 | J8: 1250000 | K8: =+I8+J8 -> 1534580.8 | L8: =K8*(1+188880/9211560) -> 1566046.9 | M8: 50000 | N8: =+L8+M8 -> 1616046.9 | O8: =N8*(1+229880/10807440) -> 1650421.1 | P8: 130000 | Q8: =+O8+P8 -> 1780421.1 | R8: =Q8*(1+258720/12010320) -> 1818774 | S8: 50000 | T8: =+R8+S8 -> 1868774 | U8: =T8*(1+276600/13176040) -> 1908004.5 | V8: 1250000 | W8: =+U8+V8 -> 3158004.5 | X8: =W8*(1+281720/15349640) -> 3215965 | Y8: 100000 | Z8: =+X8+Y8 -> 3315965 | AA8: =Z8*(1+313600/16586360) -> 3378660.3 | AB8: 100000 | AC8: =+AA8+AB8 -> 3478660.3 | AD8: =AC8*(1+321600/17662960) -> 3541998.3 | AE8: 150000 | AF8: =+AD8+AE8 -> 3691998.3 | AG8: =AF8*(1+333320/18946560) -> 3756950.3 | AI8: =+AG8+AH8 -> 3756950.3 | AJ8: =AI8*(1+1/19279881) -> 3756950.5 | AK8: =B8+D8+G8+J8+M8+P8+S8+V8+Y8+AB8+AE8+AH8 -> 3356100 | AL8: =-AK8+AJ8 -> 400850.52 | AM8: =Tableau4[[#This Row],[EP TOTALE]]+Tableau4[[#This Row],[INTERETS]] -> 3756950.5 | AN8: =Tableau4[[#This Row],[EP TOTALE]]*AK$40 -> 0
A9: EWALA Jacques Philippe | B9: 19000 | C9: =B9*(1+38000/4317300) -> 19167.234 | D9: 81000 | E9: =+D9+C9 -> 100167.23 | F9: =E9*(1+57680/5852300) -> 101154.48 | H9: =+F9+G9 -> 101154.48 | I9: =H9*(1+168480/7089080) -> 103558.53 | K9: =+I9+J9 -> 103558.53 | L9: =K9*(1+188880/9211560) -> 105681.96 | N9: =+L9+M9 -> 105681.96 | O9: =N9*(1+229880/10807440) -> 107929.87 | Q9: =+O9+P9 -> 107929.87 | R9: =Q9*(1+258720/12010320) -> 110254.84 | T9: =+R9+S9 -> 110254.84 | U9: =T9*(1+276600/13176040) -> 112569.38 | W9: =+U9+V9 -> 112569.38 | X9: =W9*(1+281720/15349640) -> 114635.43 | Z9: =+X9+Y9 -> 114635.43 | AA9: =Z9*(1+313600/16586360) -> 116802.85 | AB9: 0 | AC9: =+AA9+AB9 -> 116802.85 | AD9: =AC9*(1+321600/17662960) -> 118929.55 | AF9: =+AD9+AE9 -> 118929.55 | AG9: =AF9*(1+333320/18946560) -> 121021.84 | AI9: =+AG9+AH9 -> 121021.84 | AJ9: =AI9*(1+1/19279881) -> 121021.84 | AK9: =B9+D9+G9+J9+M9+P9+S9+V9+Y9+AB9+AE9+AH9 -> 100000 | AL9: =-AK9+AJ9 -> 21021.842 | AM9: =Tableau4[[#This Row],[EP TOTALE]]+Tableau4[[#This Row],[INTERETS]] -> 121021.84 | AN9: =Tableau4[[#This Row],[EP TOTALE]]*AK$40 -> 0
A10: FOTUE KAMGUE Kevin | B10: 100000 | C10: =B10*(1+38000/4317300) -> 100880.18 | E10: =+D10+C10 -> 100880.18 | F10: =E10*(1+57680/5852300) -> 101874.45 | H10: =+F10+G10 -> 101874.45 | I10: =H10*(1+168480/7089080) -> 104295.61 | K10: =+I10+J10 -> 104295.61 | L10: =K10*(1+188880/9211560) -> 106434.16 | N10: =+L10+M10 -> 106434.16 | O10: =N10*(1+229880/10807440) -> 108698.07 | Q10: =+O10+P10 -> 108698.07 | R10: =Q10*(1+258720/12010320) -> 111039.59 | T10: =+R10+S10 -> 111039.59 | U10: =T10*(1+276600/13176040) -> 113370.6 | W10: =+U10+V10 -> 113370.6 | X10: =W10*(1+281720/15349640) -> 115451.35 | Z10: =+X10+Y10 -> 115451.35 | AA10: =Z10*(1+313600/16586360) -> 117634.2 | AC10: =+AA10+AB10 -> 117634.2 | AD10: =AC10*(1+321600/17662960) -> 119776.04 | AF10: =+AD10+AE10 -> 119776.04 | AG10: =AF10*(1+333320/18946560) -> 121883.21 | AI10: =+AG10+AH10 -> 121883.21 | AJ10: =AI10*(1+1/19279881) -> 121883.22 | AK10: =B10+D10+G10+J10+M10+P10+S10+V10+Y10+AB10+AE10+AH10 -> 100000 | AL10: =-AK10+AJ10 -> 21883.221 | AM10: =Tableau4[[#This Row],[EP TOTALE]]+Tableau4[[#This Row],[INTERETS]] -> 121883.22 | AN10: =Tableau4[[#This Row],[EP TOTALE]]*AK$40 -> 0
A11: IPOULE Michel Landry | B11: 94000 | C11: =B11*(1+38000/4317300) -> 94827.369 | E11: =+D11+C11 -> 94827.369 | F11: =E11*(1+57680/5852300) -> 95761.983 | H11: =+F11+G11 -> 95761.983 | I11: =H11*(1+168480/7089080) -> 98037.875 | K11: =+I11+J11 -> 98037.875 | L11: =K11*(1+188880/9211560) -> 100048.11 | N11: =+L11+M11 -> 100048.11 | O11: =N11*(1+229880/10807440) -> 102176.19 | Q11: =+O11+P11 -> 102176.19 | R11: =Q11*(1+258720/12010320) -> 104377.21 | T11: =+R11+S11 -> 104377.21 | U11: =T11*(1+276600/13176040) -> 106568.37 | W11: =+U11+V11 -> 106568.37 | X11: =W11*(1+281720/15349640) -> 108524.27 | Z11: =+X11+Y11 -> 108524.27 | AA11: =Z11*(1+313600/16586360) -> 110576.15 | AB11: 6000 | AC11: =+AA11+AB11 -> 116576.15 | AD11: =AC11*(1+321600/17662960) -> 118698.72 | AF11: =+AD11+AE11 -> 118698.72 | AG11: =AF11*(1+333320/18946560) -> 120786.95 | AI11: =+AG11+AH11 -> 120786.95 | AJ11: =AI11*(1+1/19279881) -> 120786.95 | AK11: =B11+D11+G11+J11+M11+P11+S11+V11+Y11+AB11+AE11+AH11 -> 100000 | AL11: =-AK11+AJ11 -> 20786.952 | AM11: =Tableau4[[#This Row],[EP TOTALE]]+Tableau4[[#This Row],[INTERETS]] -> 120786.95 | AN11: =Tableau4[[#This Row],[EP TOTALE]]*AK$40 -> 0
A12: ITOP Samuel | B12: 200000 | C12: =B12*(1+38000/4317300) -> 201760.36 | D12: 100000 | E12: =+D12+C12 -> 301760.36 | F12: =E12*(1+57680/5852300) -> 304734.5 | G12: 200000 | H12: =+F12+G12 -> 504734.5 | I12: =H12*(1+168480/7089080) -> 516730.08 | J12: 200000 | K12: =+I12+J12 -> 716730.08 | L12: =K12*(1+188880/9211560) -> 731426.4 | M12: 100000 | N12: =+L12+M12 -> 831426.4 | O12: =N12*(1+229880/10807440) -> 849111.28 | P12: 100000 | Q12: =+O12+P12 -> 949111.28 | R12: =Q12*(1+258720/12010320) -> 969556.53 | S12: 100000 | T12: =+R12+S12 -> 1069556.5 | U12: =T12*(1+276600/13176040) -> 1092009.4 | V12: 100000 | W12: =+U12+V12 -> 1192009.4 | X12: =W12*(1+281720/15349640) -> 1213886.9 | Y12: 100000 | Z12: =+X12+Y12 -> 1313886.9 | AA12: =Z12*(1+313600/16586360) -> 1338728.7 | AB12: 100000 | AC12: =+AA12+AB12 -> 1438728.7 | AD12: =AC12*(1+321600/17662960) -> 1464924.5 | AE12: 100000 | AF12: =+AD12+AE12 -> 1564924.5 | AG12: =AF12*(1+333320/18946560) -> 1592455.7 | AI12: =+AG12+AH12 -> 1592455.7 | AJ12: =AI12*(1+1/19279881) -> 1592455.8 | AK12: =B12+D12+G12+J12+M12+P12+S12+V12+Y12+AB12+AE12+AH12 -> 1400000 | AL12: =-AK12+AJ12 -> 192455.75 | AM12: =Tableau4[[#This Row],[EP TOTALE]]+Tableau4[[#This Row],[INTERETS]] -> 1592455.8 | AN12: =Tableau4[[#This Row],[EP TOTALE]]*AK$40 -> 0
A13: LIKENG BALEBA | B13: 100000 | C13: =B13*(1+38000/4317300) -> 100880.18 | E13: =+D13+C13 -> 100880.18 | F13: =E13*(1+57680/5852300) -> 101874.45 | H13: =+F13+G13 -> 101874.45 | I13: =H13*(1+168480/7089080) -> 104295.61 | J13: 2000 | K13: =+I13+J13 -> 106295.61 | L13: =K13*(1+188880/9211560) -> 108475.17 | N13: =+L13+M13 -> 108475.17 | O13: =N13*(1+229880/10807440) -> 110782.49 | Q13: =+O13+P13 -> 110782.49 | R13: =Q13*(1+258720/12010320) -> 113168.91 | T13: =+R13+S13 -> 113168.91 | U13: =T13*(1+276600/13176040) -> 115544.63 | V13: 5000 | W13: =+U13+V13 -> 120544.63 | X13: =W13*(1+281720/15349640) -> 122757.05 | Z13: =+X13+Y13 -> 122757.05 | AA13: =Z13*(1+313600/16586360) -> 125078.03 | AC13: =+AA13+AB13 -> 125078.03 | AD13: =AC13*(1+321600/17662960) -> 127355.39 | AE13: 18000 | AF13: =+AD13+AE13 -> 145355.39 | AG13: =AF13*(1+333320/18946560) -> 147912.58 | AI13: =+AG13+AH13 -> 147912.58 | AJ13: =AI13*(1+1/19279881) -> 147912.59 | AK13: =B13+D13+G13+J13+M13+P13+S13+V13+Y13+AB13+AE13+AH13 -> 125000 | AL13: =-AK13+AJ13 -> 22912.588 | AM13: =Tableau4[[#This Row],[EP TOTALE]]+Tableau4[[#This Row],[INTERETS]] -> 147912.59 | AN13: =Tableau4[[#This Row],[EP TOTALE]]*AK$40 -> 0
A14: MAMA Paul Yannick | B14: 94000 | C14: =B14*(1+38000/4317300) -> 94827.369 | E14: =+D14+C14 -> 94827.369 | F14: =E14*(1+57680/5852300) -> 95761.983 | H14: =+F14+G14 -> 95761.983 | I14: =H14*(1+168480/7089080) -> 98037.875 | J14: 38000 | K14: =+I14+J14 -> 136037.87 | L14: =K14*(1+188880/9211560) -> 138827.29 | N14: =+L14+M14 -> 138827.29 | O14: =N14*(1+229880/10807440) -> 141780.22 | Q14: =+O14+P14 -> 141780.22 | R14: =Q14*(1+258720/12010320) -> 144834.37 | T14: =+R14+S14 -> 144834.37 | U14: =T14*(1+276600/13176040) -> 147874.83 | W14: =+U14+V14 -> 147874.83 | X14: =W14*(1+281720/15349640) -> 150588.85 | Z14: =+X14+Y14 -> 150588.85 | AA14: =Z14*(1+313600/16586360) -> 153436.05 | AC14: =+AA14+AB14 -> 153436.05 | AD14: =AC14*(1+321600/17662960) -> 156229.75 | AF14: =+AD14+AE14 -> 156229.75 | AG14: =AF14*(1+333320/18946560) -> 158978.25 | AI14: =+AG14+AH14 -> 158978.25 | AJ14: =AI14*(1+1/19279881) -> 158978.26 | AK14: =B14+D14+G14+J14+M14+P14+S14+V14+Y14+AB14+AE14+AH14 -> 132000 | AL14: =-AK14+AJ14 -> 26978.256 | AM14: =Tableau4[[#This Row],[EP TOTALE]]+Tableau4[[#This Row],[INTERETS]] -> 158978.26 | AN14: =Tableau4[[#This Row],[EP TOTALE]]*AK$40 -> 0
A15: MANI EKOUDI François M. | B15: 0 | C15: =B15*(1+38000/4317300) -> 0 | D15: 10000 | E15: =+D15+C15 -> 10000 | F15: =E15*(1+57680/5852300) -> 10098.56 | G15: 20000 | H15: =+F15+G15 -> 30098.56 | I15: =H15*(1+168480/7089080) -> 30813.886 | J15: 50000 | K15: =+I15+J15 -> 80813.886 | L15: =K15*(1+188880/9211560) -> 82470.948 | M15: 100000 | N15: =+L15+M15 -> 182470.95 | O15: =N15*(1+229880/10807440) -> 186352.2 | Q15: =+O15+P15 -> 186352.2 | R15: =Q15*(1+258720/12010320) -> 190366.5 | T15: =+R15+S15 -> 190366.5 | U15: =T15*(1+276600/13176040) -> 194362.8 | W15: =+U15+V15 -> 194362.8 | X15: =W15*(1+281720/15349640) -> 197930.04 | Z15: =+X15+Y15 -> 197930.04 | AA15: =Z15*(1+313600/16586360) -> 201672.33 | AC15: =+AA15+AB15 -> 201672.33 | AD15: =AC15*(1+321600/17662960) -> 205344.29 | AF15: =+AD15+AE15 -> 205344.29 | AG15: =AF15*(1+333320/18946560) -> 208956.84 | AI15: =+AG15+AH15 -> 208956.84 | AJ15: =AI15*(1+1/19279881) -> 208956.85 | AK15: =B15+D15+G15+J15+M15+P15+S15+V15+Y15+AB15+AE15+AH15 -> 180000 | AL15: =-AK15+AJ15 -> 28956.853 | AM15: =Tableau4[[#This Row],[EP TOTALE]]+Tableau4[[#This Row],[INTERETS]] -> 208956.85 | AN15: =Tableau4[[#This Row],[EP TOTALE]]*AK$40 -> 0
A16: MBA ENYOUGOU Bernard | B16: 52000 | C16: =B16*(1+38000/4317300) -> 52457.693 | E16: =+D16+C16 -> 52457.693 | F16: =E16*(1+57680/5852300) -> 52974.714 | G16: 20000 | H16: =+F16+G16 -> 72974.714 | I16: =H16*(1+168480/7089080) -> 74709.041 | J16: 10000 | K16: =+I16+J16 -> 84709.041 | L16: =K16*(1+188880/9211560) -> 86445.972 | N16: =+L16+M16 -> 86445.972 | O16: =N16*(1+229880/10807440) -> 88284.723 | Q16: =+O16+P16 -> 88284.723 | R16: =Q16*(1+258720/12010320) -> 90186.507 | T16: =+R16+S16 -> 90186.507 | U16: =T16*(1+276600/13176040) -> 92079.76 | W16: =+U16+V16 -> 92079.76 | X16: =W16*(1+281720/15349640) -> 93769.748 | Z16: =+X16+Y16 -> 93769.748 | AA16: =Z16*(1+313600/16586360) -> 95542.663 | AB16: 7000 | AC16: =+AA16+AB16 -> 102542.66 | AD16: =AC16*(1+321600/17662960) -> 104409.72 | AF16: =+AD16+AE16 -> 104409.72 | AG16: =AF16*(1+333320/18946560) -> 106246.56 | AI16: =+AG16+AH16 -> 106246.56 | AJ16: =AI16*(1+1/19279881) -> 106246.57 | AK16: =B16+D16+G16+J16+M16+P16+S16+V16+Y16+AB16+AE16+AH16 -> 89000 | AL16: =-AK16+AJ16 -> 17246.566 | AM16: =Tableau4[[#This Row],[EP TOTALE]]+Tableau4[[#This Row],[INTERETS]] -> 106246.57 | AN16: =Tableau4[[#This Row],[EP TOTALE]]*AK$40 -> 0
A17: MBADI Homer Paul | B17: 33000 | C17: =B17*(1+38000/4317300) -> 33290.459 | D17: 1000000 | E17: =+D17+C17 -> 1033290.5 | F17: =E17*(1+57680/5852300) -> 1043474.5 | G17: 500000 | H17: =+F17+G17 -> 1543474.5 | I17: =H17*(1+168480/7089080) -> 1580156.9 | K17: =+I17+J17 -> 1580156.9 | L17: =K17*(1+188880/9211560) -> 1612557.5 | M17: 500000 | N17: =+L17+M17 -> 2112557.5 | O17: =N17*(1+229880/10807440) -> 2157492.8 | P17: 500000 | Q17: =+O17+P17 -> 2657492.8 | R17: =Q17*(1+258720/12010320) -> 2714739.1 | S17: 500000 | T17: =+R17+S17 -> 3214739.1 | U17: =T17*(1+276600/13176040) -> 3282225 | V17: 500000 | W17: =+U17+V17 -> 3782225 | X17: =W17*(1+281720/15349640) -> 3851642.1 | Y17: 500000 | Z17: =+X17+Y17 -> 4351642.1 | AA17: =Z17*(1+313600/16586360) -> 4433919.1 | AB17: 500000 | AC17: =+AA17+AB17 -> 4933919.1 | AD17: =AC17*(1+321600/17662960) -> 5023753.9 | AE17: 500000 | AF17: =+AD17+AE17 -> 5523753.9 | AG17: =AF17*(1+333320/18946560) -> 5620931.3 | AI17: =+AG17+AH17 -> 5620931.3 | AJ17: =AI17*(1+1/19279881) -> 5620931.6 | AK17: =B17+D17+G17+J17+M17+P17+S17+V17+Y17+AB17+AE17+AH17 -> 5033000 | AL17: =-AK17+AJ17 -> 587931.56 | AM17: =Tableau4[[#This Row],[EP TOTALE]]+Tableau4[[#This Row],[INTERETS]] -> 5620931.6 | AN17: =Tableau4[[#This Row],[EP TOTALE]]*AK$40 -> 0
A18: MBAMBA NSOA Jean Paul | B18: 200000 | C18: =B18*(1+38000/4317300) -> 201760.36 | D18: 100000 | E18: =+D18+C18 -> 301760.36 | F18: =E18*(1+57680/5852300) -> 304734.5 | H18: =+F18+G18 -> 304734.5 | I18: =H18*(1+168480/7089080) -> 311976.86 | K18: =+I18+J18 -> 311976.86 | L18: =K18*(1+188880/9211560) -> 318373.84 | M18: 100000 | N18: =+L18+M18 -> 418373.84 | O18: =N18*(1+229880/10807440) -> 427272.87 | Q18: =+O18+P18 -> 427272.87 | R18: =Q18*(1+258720/12010320) -> 436476.96 | S18: 100000 | T18: =+R18+S18 -> 536476.96 | U18: =T18*(1+276600/13176040) -> 547739.03 | W18: =+U18+V18 -> 547739.03 | X18: =W18*(1+281720/15349640) -> 557791.98 | Z18: =+X18+Y18 -> 557791.98 | AA18: =Z18*(1+313600/16586360) -> 568338.2 | AC18: =+AA18+AB18 -> 568338.2 | AD18: =AC18*(1+321600/17662960) -> 578686.28 | AE18: 18000 | AF18: =+AD18+AE18 -> 596686.28 | AG18: =AF18*(1+333320/18946560) -> 607183.56 | AI18: =+AG18+AH18 -> 607183.56 | AJ18: =AI18*(1+1/19279881) -> 607183.59 | AK18: =B18+D18+G18+J18+M18+P18+S18+V18+Y18+AB18+AE18+AH18 -> 518000 | AL18: =-AK18+AJ18 -> 89183.594 | AM18: =Tableau4[[#This Row],[EP TOTALE]]+Tableau4[[#This Row],[INTERETS]] -> 607183.59 | AN18: =Tableau4[[#This Row],[EP TOTALE]]*AK$40 -> 0
A19: MENGUE François Xavier | B19: 40000 | C19: =B19*(1+38000/4317300) -> 40352.072 | E19: =+D19+C19 -> 40352.072 | F19: =E19*(1+57680/5852300) -> 40749.78 | H19: =+F19+G19 -> 40749.78 | I19: =H19*(1+168480/7089080) -> 41718.245 | K19: =+I19+J19 -> 41718.245 | L19: =K19*(1+188880/9211560) -> 42573.664 | N19: =+L19+M19 -> 42573.664 | O19: =N19*(1+229880/10807440) -> 43479.228 | P19: 88000 | Q19: =+O19+P19 -> 131479.23 | R19: =Q19*(1+258720/12010320) -> 134311.48 | T19: =+R19+S19 -> 134311.48 | U19: =T19*(1+276600/13176040) -> 137131.04 | W19: =+U19+V19 -> 137131.04 | X19: =W19*(1+281720/15349640) -> 139647.88 | Z19: =+X19+Y19 -> 139647.88 | AA19: =Z19*(1+313600/16586360) -> 142288.21 | AC19: =+AA19+AB19 -> 142288.21 | AD19: =AC19*(1+321600/17662960) -> 144878.94 | AF19: =+AD19+AE19 -> 144878.94 | AG19: =AF19*(1+333320/18946560) -> 147427.74 | AI19: =+AG19+AH19 -> 147427.74 | AJ19: =AI19*(1+1/19279881) -> 147427.75 | AK19: =B19+D19+G19+J19+M19+P19+S19+V19+Y19+AB19+AE19+AH19 -> 128000 | AL19: =-AK19+AJ19 -> 19427.75 | AM19: =Tableau4[[#This Row],[EP TOTALE]]+Tableau4[[#This Row],[INTERETS]] -> 147427.75 | AN19: =Tableau4[[#This Row],[EP TOTALE]]*AK$40 -> 0
A20: MIONG RIGOBERT Dieudonné | B20: 100000 | C20: =B20*(1+38000/4317300) -> 100880.18 | E20: =+D20+C20 -> 100880.18 | F20: =E20*(1+57680/5852300) -> 101874.45 | H20: =+F20+G20 -> 101874.45 | I20: =H20*(1+168480/7089080) -> 104295.61 | J20: 20000 | K20: =+I20+J20 -> 124295.61 | L20: =K20*(1+188880/9211560) -> 126844.25 | N20: =+L20+M20 -> 126844.25 | O20: =N20*(1+229880/10807440) -> 129542.3 | Q20: =+O20+P20 -> 129542.3 | R20: =Q20*(1+258720/12010320) -> 132332.83 | T20: =+R20+S20 -> 132332.83 | U20: =T20*(1+276600/13176040) -> 135110.85 | W20: =+U20+V20 -> 135110.85 | X20: =W20*(1+281720/15349640) -> 137590.61 | Z20: =+X20+Y20 -> 137590.61 | AA20: =Z20*(1+313600/16586360) -> 140192.05 | AC20: =+AA20+AB20 -> 140192.05 | AD20: =AC20*(1+321600/17662960) -> 142744.61 | AF20: =+AD20+AE20 -> 142744.61 | AG20: =AF20*(1+333320/18946560) -> 145255.86 | AI20: =+AG20+AH20 -> 145255.86 | AJ20: =AI20*(1+1/19279881) -> 145255.87 | AK20: =B20+D20+G20+J20+M20+P20+S20+V20+Y20+AB20+AE20+AH20 -> 120000 | AL20: =-AK20+AJ20 -> 25255.867 | AM20: =Tableau4[[#This Row],[EP TOTALE]]+Tableau4[[#This Row],[INTERETS]] -> 145255.87 | AN20: =Tableau4[[#This Row],[EP TOTALE]]*AK$40 -> 0
A21: NDJOCK Thaddée Rodrigue | B21: 0 | C21: =B21*(1+38000/4317300) -> 0 | E21: =+D21+C21 -> 0 | F21: =E21*(1+57680/5852300) -> 0 | G21: 6000 | H21: =+F21+G21 -> 6000 | I21: =H21*(1+168480/7089080) -> 6142.5968 | K21: =+I21+J21 -> 6142.5968 | L21: =K21*(1+188880/9211560) -> 6268.5487 | N21: =+L21+M21 -> 6268.5487 | O21: =N21*(1+229880/10807440) -> 6401.8841 | Q21: =+O21+P21 -> 6401.8841 | R21: =Q21*(1+258720/12010320) -> 6539.7901 | T21: =+R21+S21 -> 6539.7901 | U21: =T21*(1+276600/13176040) -> 6677.0776 | W21: =+U21+V21 -> 6677.0776 | X21: =W21*(1+281720/15349640) -> 6799.6255 | Z21: =+X21+Y21 -> 6799.6255 | AA21: =Z21*(1+313600/16586360) -> 6928.1867 | AC21: =+AA21+AB21 -> 6928.1867 | AD21: =AC21*(1+321600/17662960) -> 7054.3324 | AF21: =+AD21+AE21 -> 7054.3324 | AG21: =AF21*(1+333320/18946560) -> 7178.4367 | AI21: =+AG21+AH21 -> 7178.4367 | AJ21: =AI21*(1+1/19279881) -> 7178.4371 | AK21: =B21+D21+G21+J21+M21+P21+S21+V21+Y21+AB21+AE21+AH21 -> 6000 | AL21: =-AK21+AJ21 -> 1178.4371 | AM21: =Tableau4[[#This Row],[EP TOTALE]]+Tableau4[[#This Row],[INTERETS]] -> 7178.4371 | AN21: =Tableau4[[#This Row],[EP TOTALE]]*AK$40 -> 0
A22: NKOLO NGAH Emmanuel | B22: 100000 | C22: =B22*(1+38000/4317300) -> 100880.18 | E22: =+D22+C22 -> 100880.18 | F22: =E22*(1+57680/5852300) -> 101874.45 | H22: =+F22+G22 -> 101874.45 | I22: =H22*(1+168480/7089080) -> 104295.61 | K22: =+I22+J22 -> 104295.61 | L22: =K22*(1+188880/9211560) -> 106434.16 | N22: =+L22+M22 -> 106434.16 | O22: =N22*(1+229880/10807440) -> 108698.07 | Q22: =+O22+P22 -> 108698.07 | R22: =Q22*(1+258720/12010320) -> 111039.59 | T22: =+R22+S22 -> 111039.59 | U22: =T22*(1+276600/13176040) -> 113370.6 | W22: =+U22+V22 -> 113370.6 | X22: =W22*(1+281720/15349640) -> 115451.35 | Z22: =+X22+Y22 -> 115451.35 | AA22: =Z22*(1+313600/16586360) -> 117634.2 | AC22: =+AA22+AB22 -> 117634.2 | AD22: =AC22*(1+321600/17662960) -> 119776.04 | AE22: 8000 | AF22: =+AD22+AE22 -> 127776.04 | AG22: =AF22*(1+333320/18946560) -> 130023.96 | AI22: =+AG22+AH22 -> 130023.96 | AJ22: =AI22*(1+1/19279881) -> 130023.96 | AK22: =B22+D22+G22+J22+M22+P22+S22+V22+Y22+AB22+AE22+AH22 -> 108000 | AL22: =-AK22+AJ22 -> 22023.963 | AM22: =Tableau4[[#This Row],[EP TOTALE]]+Tableau4[[#This Row],[INTERETS]] -> 130023.96 | AN22: =Tableau4[[#This Row],[EP TOTALE]]*AK$40 -> 0
A23: NOAH Patrick Michel Brice | C23: =B23*(1+38000/4317300) -> 0 | E23: =+D23+C23 -> 0 | F23: =E23*(1+57680/5852300) -> 0 | G23: 100000 | H23: =+F23+G23 -> 100000 | I23: =H23*(1+168480/7089080) -> 102376.61 | K23: =+I23+J23 -> 102376.61 | L23: =K23*(1+188880/9211560) -> 104475.81 | M23: 100000 | N23: =+L23+M23 -> 204475.81 | O23: =N23*(1+229880/10807440) -> 208825.12 | Q23: =+O23+P23 -> 208825.12 | R23: =Q23*(1+258720/12010320) -> 213323.52 | T23: =+R23+S23 -> 213323.52 | U23: =T23*(1+276600/13176040) -> 217801.75 | W23: =+U23+V23 -> 217801.75 | X23: =W23*(1+281720/15349640) -> 221799.18 | Z23: =+X23+Y23 -> 221799.18 | AA23: =Z23*(1+313600/16586360) -> 225992.76 | AC23: =+AA23+AB23 -> 225992.76 | AD23: =AC23*(1+321600/17662960) -> 230107.54 | AF23: =+AD23+AE23 -> 230107.54 | AG23: =AF23*(1+333320/18946560) -> 234155.74 | AI23: =+AG23+AH23 -> 234155.74 | AJ23: =AI23*(1+1/19279881) -> 234155.75 | AK23: =B23+D23+G23+J23+M23+P23+S23+V23+Y23+AB23+AE23+AH23 -> 200000 | AL23: =-AK23+AJ23 -> 34155.753 | AM23: =Tableau4[[#This Row],[EP TOTALE]]+Tableau4[[#This Row],[INTERETS]] -> 234155.75 | AN23: =Tableau4[[#This Row],[EP TOTALE]]*AK$40 -> 0
A24: NONBO Marc | B24: 0 | C24: =B24*(1+38000/4317300) -> 0 | E24: =+D24+C24 -> 0 | F24: =E24*(1+57680/5852300) -> 0 | H24: =+F24+G24 -> 0 | I24: =H24*(1+168480/7089080) -> 0 | K24: =+I24+J24 -> 0 | L24: =K24*(1+188880/9211560) -> 0 | N24: =+L24+M24 -> 0 | O24: =N24*(1+229880/10807440) -> 0 | Q24: =+O24+P24 -> 0 | R24: =Q24*(1+258720/12010320) -> 0 | T24: =+R24+S24 -> 0 | U24: =T24*(1+276600/13176040) -> 0 | W24: =+U24+V24 -> 0 | X24: =W24*(1+281720/15349640) -> 0 | Y24: 100000 | Z24: =+X24+Y24 -> 100000 | AA24: =Z24*(1+313600/16586360) -> 101890.71 | AC24: =+AA24+AB24 -> 101890.71 | AD24: =AC24*(1+321600/17662960) -> 103745.89 | AF24: =+AD24+AE24 -> 103745.89 | AG24: =AF24*(1+333320/18946560) -> 105571.06 | AI24: =+AG24+AH24 -> 105571.06 | AJ24: =AI24*(1+1/19279881) -> 105571.06 | AK24: =B24+D24+G24+J24+M24+P24+S24+V24+Y24+AB24+AE24+AH24 -> 100000 | AL24: =-AK24+AJ24 -> 5571.0645 | AM24: =Tableau4[[#This Row],[EP TOTALE]]+Tableau4[[#This Row],[INTERETS]] -> 105571.06 | AN24: =Tableau4[[#This Row],[EP TOTALE]]*AK$40 -> 0
A25: NSOA MBONDO Pierre | B25: 100500 | C25: =B25*(1+38000/4317300) -> 101384.58 | E25: =+D25+C25 -> 101384.58 | F25: =E25*(1+57680/5852300) -> 102383.82 | H25: =+F25+G25 -> 102383.82 | I25: =H25*(1+168480/7089080) -> 104817.09 | K25: =+I25+J25 -> 104817.09 | L25: =K25*(1+188880/9211560) -> 106966.33 | N25: =+L25+M25 -> 106966.33 | O25: =N25*(1+229880/10807440) -> 109241.56 | Q25: =+O25+P25 -> 109241.56 | R25: =Q25*(1+258720/12010320) -> 111594.78 | T25: =+R25+S25 -> 111594.78 | U25: =T25*(1+276600/13176040) -> 113937.45 | W25: =+U25+V25 -> 113937.45 | X25: =W25*(1+281720/15349640) -> 116028.61 | Z25: =+X25+Y25 -> 116028.61 | AA25: =Z25*(1+313600/16586360) -> 118222.37 | AC25: =+AA25+AB25 -> 118222.37 | AD25: =AC25*(1+321600/17662960) -> 120374.92 | AF25: =+AD25+AE25 -> 120374.92 | AG25: =AF25*(1+333320/18946560) -> 122492.63 | AI25: =+AG25+AH25 -> 122492.63 | AJ25: =AI25*(1+1/19279881) -> 122492.64 | AK25: =B25+D25+G25+J25+M25+P25+S25+V25+Y25+AB25+AE25+AH25 -> 100500 | AL25: =-AK25+AJ25 -> 21992.637 | AM25: =Tableau4[[#This Row],[EP TOTALE]]+Tableau4[[#This Row],[INTERETS]] -> 122492.64 | AN25: =Tableau4[[#This Row],[EP TOTALE]]*AK$40 -> 0
A26: NSOE NKOULI Jean-Baptiste | B26: 100000 | C26: =B26*(1+38000/4317300) -> 100880.18 | E26: =+D26+C26 -> 100880.18 | F26: =E26*(1+57680/5852300) -> 101874.45 | H26: =+F26+G26 -> 101874.45 | I26: =H26*(1+168480/7089080) -> 104295.61 | K26: =+I26+J26 -> 104295.61 | L26: =K26*(1+188880/9211560) -> 106434.16 | N26: =+L26+M26 -> 106434.16 | O26: =N26*(1+229880/10807440) -> 108698.07 | Q26: =+O26+P26 -> 108698.07 | R26: =Q26*(1+258720/12010320) -> 111039.59 | T26: =+R26+S26 -> 111039.59 | U26: =T26*(1+276600/13176040) -> 113370.6 | W26: =+U26+V26 -> 113370.6 | X26: =W26*(1+281720/15349640) -> 115451.35 | Y26: 0 | Z26: =+X26+Y26 -> 115451.35 | AA26: =Z26*(1+313600/16586360) -> 117634.2 | AC26: =+AA26+AB26 -> 117634.2 | AD26: =AC26*(1+321600/17662960) -> 119776.04 | AE26: 150000 | AF26: =+AD26+AE26 -> 269776.04 | AG26: =AF26*(1+333320/18946560) -> 274522.11 | AI26: =+AG26+AH26 -> 274522.11 | AJ26: =AI26*(1+1/19279881) -> 274522.13 | AK26: =B26+D26+G26+J26+M26+P26+S26+V26+Y26+AB26+AE26+AH26 -> 250000 | AL26: =-AK26+AJ26 -> 24522.125 | AM26: =Tableau4[[#This Row],[EP TOTALE]]+Tableau4[[#This Row],[INTERETS]] -> 274522.13 | AN26: =Tableau4[[#This Row],[EP TOTALE]]*AK$40 -> 0
A27: NYECK PONDI Etienne | B27: 600000 | C27: =B27*(1+38000/4317300) -> 605281.08 | E27: =+D27+C27 -> 605281.08 | F27: =E27*(1+57680/5852300) -> 611246.7 | H27: =+F27+G27 -> 611246.7 | I27: =H27*(1+168480/7089080) -> 625773.67 | K27: =+I27+J27 -> 625773.67 | L27: =K27*(1+188880/9211560) -> 638604.95 | M27: 150000 | N27: =+L27+M27 -> 788604.95 | O27: =N27*(1+229880/10807440) -> 805379 | Q27: =+O27+P27 -> 805379 | R27: =Q27*(1+258720/12010320) -> 822728.05 | T27: =+R27+S27 -> 822728.05 | U27: =T27*(1+276600/13176040) -> 839999.29 | W27: =+U27+V27 -> 839999.29 | X27: =W27*(1+281720/15349640) -> 855416.24 | Z27: =+X27+Y27 -> 855416.24 | AA27: =Z27*(1+313600/16586360) -> 871589.68 | AC27: =+AA27+AB27 -> 871589.68 | AD27: =AC27*(1+321600/17662960) -> 887459.23 | AF27: =+AD27+AE27 -> 887459.23 | AG27: =AF27*(1+333320/18946560) -> 903071.98 | AI27: =+AG27+AH27 -> 903071.98 | AJ27: =AI27*(1+1/19279881) -> 903072.03 | AK27: =B27+D27+G27+J27+M27+P27+S27+V27+Y27+AB27+AE27+AH27 -> 750000 | AL27: =-AK27+AJ27 -> 153072.03 | AM27: =Tableau4[[#This Row],[EP TOTALE]]+Tableau4[[#This Row],[INTERETS]] -> 903072.03 | AN27: =Tableau4[[#This Row],[EP TOTALE]]*AK$40 -> 0
A28: OMGBA FOUDA Simon Pierre | B28: 54000 | C28: =B28*(1+38000/4317300) -> 54475.297 | D28: 100000 | E28: =+D28+C28 -> 154475.3 | F28: =E28*(1+57680/5852300) -> 155997.8 | G28: 50000 | H28: =+F28+G28 -> 205997.8 | I28: =H28*(1+168480/7089080) -> 210893.57 | K28: =+I28+J28 -> 210893.57 | L28: =K28*(1+188880/9211560) -> 215217.87 | N28: =+L28+M28 -> 215217.87 | O28: =N28*(1+229880/10807440) -> 219795.67 | Q28: =+O28+P28 -> 219795.67 | R28: =Q28*(1+258720/12010320) -> 224530.39 | T28: =+R28+S28 -> 224530.39 | U28: =T28*(1+276600/13176040) -> 229243.88 | W28: =+U28+V28 -> 229243.88 | X28: =W28*(1+281720/15349640) -> 233451.31 | Y28: 100000 | Z28: =+X28+Y28 -> 333451.31 | AA28: =Z28*(1+313600/16586360) -> 339755.91 | AC28: =+AA28+AB28 -> 339755.91 | AD28: =AC28*(1+321600/17662960) -> 345942.05 | AF28: =+AD28+AE28 -> 345942.05 | AG28: =AF28*(1+333320/18946560) -> 352028.08 | AI28: =+AG28+AH28 -> 352028.08 | AJ28: =AI28*(1+1/19279881) -> 352028.1 | AK28: =B28+D28+G28+J28+M28+P28+S28+V28+Y28+AB28+AE28+AH28 -> 304000 | AL28: =-AK28+AJ28 -> 48028.103 | AM28: =Tableau4[[#This Row],[EP TOTALE]]+Tableau4[[#This Row],[INTERETS]] -> 352028.1 | AN28: =Tableau4[[#This Row],[EP TOTALE]]*AK$40 -> 0
A29: OMGBA MIMBOE Gaetan | B29: 300000 | C29: =B29*(1+38000/4317300) -> 302640.54 | D29: 50000 | E29: =+D29+C29 -> 352640.54 | F29: =E29*(1+57680/5852300) -> 356116.15 | H29: =+F29+G29 -> 356116.15 | I29: =H29*(1+168480/7089080) -> 364579.65 | J29: 97000 | K29: =+I29+J29 -> 461579.65 | L29: =K29*(1+188880/9211560) -> 471044.19 | M29: 200000 | N29: =+L29+M29 -> 671044.19 | O29: =N29*(1+229880/10807440) -> 685317.66 | P29: 50000 | Q29: =+O29+P29 -> 735317.66 | R29: =Q29*(1+258720/12010320) -> 751157.48 | T29: =+R29+S29 -> 751157.48 | U29: =T29*(1+276600/13176040) -> 766926.27 | W29: =+U29+V29 -> 766926.27 | X29: =W29*(1+281720/15349640) -> 781002.07 | Y29: 50000 | Z29: =+X29+Y29 -> 831002.07 | AA29: =Z29*(1+313600/16586360) -> 846713.91 | AC29: =+AA29+AB29 -> 846713.91 | AD29: =AC29*(1+321600/17662960) -> 862130.53 | AF29: =+AD29+AE29 -> 862130.53 | AG29: =AF29*(1+333320/18946560) -> 877297.69 | AI29: =+AG29+AH29 -> 877297.69 | AJ29: =AI29*(1+1/19279881) -> 877297.73 | AK29: =B29+D29+G29+J29+M29+P29+S29+V29+Y29+AB29+AE29+AH29 -> 747000 | AL29: =-AK29+AJ29 -> 130297.73 | AM29: =Tableau4[[#This Row],[EP TOTALE]]+Tableau4[[#This Row],[INTERETS]] -> 877297.73 | AN29: =Tableau4[[#This Row],[EP TOTALE]]*AK$40 -> 0
A30: ONANA NKADA Laurent S. | B30: 106000 | C30: =B30*(1+38000/4317300) -> 106932.99 | E30: =+D30+C30 -> 106932.99 | F30: =E30*(1+57680/5852300) -> 107986.92 | H30: =+F30+G30 -> 107986.92 | I30: =H30*(1+168480/7089080) -> 110553.35 | K30: =+I30+J30 -> 110553.35 | L30: =K30*(1+188880/9211560) -> 112820.21 | N30: =+L30+M30 -> 112820.21 | O30: =N30*(1+229880/10807440) -> 115219.95 | Q30: =+O30+P30 -> 115219.95 | R30: =Q30*(1+258720/12010320) -> 117701.96 | T30: =+R30+S30 -> 117701.96 | U30: =T30*(1+276600/13176040) -> 120172.84 | W30: =+U30+V30 -> 120172.84 | X30: =W30*(1+281720/15349640) -> 122378.43 | Y30: 5000 | Z30: =+X30+Y30 -> 127378.43 | AA30: =Z30*(1+313600/16586360) -> 129786.79 | AC30: =+AA30+AB30 -> 129786.79 | AD30: =AC30*(1+321600/17662960) -> 132149.9 | AF30: =+AD30+AE30 -> 132149.9 | AG30: =AF30*(1+333320/18946560) -> 134474.76 | AI30: =+AG30+AH30 -> 134474.76 | AJ30: =AI30*(1+1/19279881) -> 134474.77 | AK30: =B30+D30+G30+J30+M30+P30+S30+V30+Y30+AB30+AE30+AH30 -> 111000 | AL30: =-AK30+AJ30 -> 23474.768 | AM30: =Tableau4[[#This Row],[EP TOTALE]]+Tableau4[[#This Row],[INTERETS]] -> 134474.77 | AN30: =Tableau4[[#This Row],[EP TOTALE]]*AK$40 -> 0
A31: ONDOA Jean | B31: 94000 | C31: =B31*(1+38000/4317300) -> 94827.369 | E31: =+D31+C31 -> 94827.369 | F31: =E31*(1+57680/5852300) -> 95761.983 | H31: =+F31+G31 -> 95761.983 | I31: =H31*(1+168480/7089080) -> 98037.875 | K31: =+I31+J31 -> 98037.875 | L31: =K31*(1+188880/9211560) -> 100048.11 | N31: =+L31+M31 -> 100048.11 | O31: =N31*(1+229880/10807440) -> 102176.19 | P31: 88000 | Q31: =+O31+P31 -> 190176.19 | R31: =Q31*(1+258720/12010320) -> 194272.86 | T31: =+R31+S31 -> 194272.86 | U31: =T31*(1+276600/13176040) -> 198351.16 | W31: =+U31+V31 -> 198351.16 | X31: =W31*(1+281720/15349640) -> 201991.61 | Z31: =+X31+Y31 -> 201991.61 | AA31: =Z31*(1+313600/16586360) -> 205810.68 | AC31: =+AA31+AB31 -> 205810.68 | AD31: =AC31*(1+321600/17662960) -> 209558 | AF31: =+AD31+AE31 -> 209558 | AG31: =AF31*(1+333320/18946560) -> 213244.68 | AI31: =+AG31+AH31 -> 213244.68 | AJ31: =AI31*(1+1/19279881) -> 213244.69 | AK31: =B31+D31+G31+J31+M31+P31+S31+V31+Y31+AB31+AE31+AH31 -> 182000 | AL31: =-AK31+AJ31 -> 31244.689 | AM31: =Tableau4[[#This Row],[EP TOTALE]]+Tableau4[[#This Row],[INTERETS]] -> 213244.69 | AN31: =Tableau4[[#This Row],[EP TOTALE]]*AK$40 -> 0
A32: TSANGA TSANGA Christol | B32: 32800 | C32: =B32*(1+38000/4317300) -> 33088.699 | E32: =+D32+C32 -> 33088.699 | F32: =E32*(1+57680/5852300) -> 33414.82 | H32: =+F32+G32 -> 33414.82 | I32: =H32*(1+168480/7089080) -> 34208.961 | K32: =+I32+J32 -> 34208.961 | L32: =K32*(1+188880/9211560) -> 34910.404 | N32: =+L32+M32 -> 34910.404 | O32: =N32*(1+229880/10807440) -> 35652.967 | Q32: =+O32+P32 -> 35652.967 | R32: =Q32*(1+258720/12010320) -> 36420.984 | S32: 100000 | T32: =+R32+S32 -> 136420.98 | U32: =T32*(1+276600/13176040) -> 139284.82 | W32: =+U32+V32 -> 139284.82 | X32: =W32*(1+281720/15349640) -> 141841.19 | Z32: =+X32+Y32 -> 141841.19 | AA32: =Z32*(1+313600/16586360) -> 144523 | AC32: =+AA32+AB32 -> 144523 | AD32: =AC32*(1+321600/17662960) -> 147154.41 | AE32: 2000 | AF32: =+AD32+AE32 -> 149154.41 | AG32: =AF32*(1+333320/18946560) -> 151778.43 | AI32: =+AG32+AH32 -> 151778.43 | AJ32: =AI32*(1+1/19279881) -> 151778.44 | AK32: =B32+D32+G32+J32+M32+P32+S32+V32+Y32+AB32+AE32+AH32 -> 134800 | AL32: =-AK32+AJ32 -> 16978.439 | AM32: =Tableau4[[#This Row],[EP TOTALE]]+Tableau4[[#This Row],[INTERETS]] -> 151778.44 | AN32: =Tableau4[[#This Row],[EP TOTALE]]*AK$40 -> 0
A33: ZE ANDJE Eric | B33: 104000 | C33: =B33*(1+38000/4317300) -> 104915.39 | E33: =+D33+C33 -> 104915.39 | F33: =E33*(1+57680/5852300) -> 105949.43 | H33: =+F33+G33 -> 105949.43 | I33: =H33*(1+168480/7089080) -> 108467.44 | J33: 140000 | K33: =+I33+J33 -> 248467.44 | L33: =K33*(1+188880/9211560) -> 253562.18 | M33: 100000 | N33: =+L33+M33 -> 353562.18 | O33: =N33*(1+229880/10807440) -> 361082.63 | Q33: =+O33+P33 -> 361082.63 | R33: =Q33*(1+258720/12010320) -> 368860.89 | T33: =+R33+S33 -> 368860.89 | U33: =T33*(1+276600/13176040) -> 376604.25 | W33: =+U33+V33 -> 376604.25 | X33: =W33*(1+281720/15349640) -> 383516.27 | Z33: =+X33+Y33 -> 383516.27 | AA33: =Z33*(1+313600/16586360) -> 390767.45 | AC33: =+AA33+AB33 -> 390767.45 | AD33: =AC33*(1+321600/17662960) -> 397882.39 | AF33: =+AD33+AE33 -> 397882.39 | AG33: =AF33*(1+333320/18946560) -> 404882.19 | AI33: =+AG33+AH33 -> 404882.19 | AJ33: =AI33*(1+1/19279881) -> 404882.21 | AK33: =B33+D33+G33+J33+M33+P33+S33+V33+Y33+AB33+AE33+AH33 -> 344000 | AL33: =-AK33+AJ33 -> 60882.209 | AM33: =Tableau4[[#This Row],[EP TOTALE]]+Tableau4[[#This Row],[INTERETS]] -> 404882.21 | AN33: =Tableau4[[#This Row],[EP TOTALE]]*AK$40 -> 0
A34: SECOURS / CAYA | B34: 500000 | C34: =B34*(1+38000/4317300) -> 504400.9 | E34: =+D34+C34 -> 504400.9 | F34: =E34*(1+57680/5852300) -> 509372.25 | H34: =+F34+G34 -> 509372.25 | I34: =H34*(1+168480/7089080) -> 521478.06 | K34: =+I34+J34 -> 521478.06 | L34: =K34*(1+188880/9211560) -> 532170.79 | N34: =+L34+M34 -> 532170.79 | O34: =N34*(1+229880/10807440) -> 543490.35 | Q34: =+O34+P34 -> 543490.35 | R34: =Q34*(1+258720/12010320) -> 555197.93 | T34: =+R34+S34 -> 555197.93 | U34: =T34*(1+276600/13176040) -> 566853.01 | W34: =+U34+V34 -> 566853.01 | X34: =W34*(1+281720/15349640) -> 577256.76 | Z34: =+X34+Y34 -> 577256.76 | AA34: =Z34*(1+313600/16586360) -> 588171.01 | AC34: =+AA34+AB34 -> 588171.01 | AD34: =AC34*(1+321600/17662960) -> 598880.19 | AF34: =+AD34+AE34 -> 598880.19 | AG34: =AF34*(1+333320/18946560) -> 609416.07 | AI34: =+AG34+AH34 -> 609416.07 | AJ34: =AI34*(1+1/19279881) -> 609416.11 | AK34: =B34+D34+G34+J34+M34+P34+S34+V34+Y34+AB34+AE34+AH34 -> 500000 | AL34: =-AK34+AJ34 -> 109416.11 | AM34: =Tableau4[[#This Row],[EP TOTALE]]+Tableau4[[#This Row],[INTERETS]] -> 609416.11 | AN34: =Tableau4[[#This Row],[EP TOTALE]]*AK$40 -> 0
A35: BUREAU | B35: 410000 | C35: =B35*(1+38000/4317300) -> 413608.74 | E35: =+D35+C35 -> 413608.74 | F35: =E35*(1+57680/5852300) -> 417685.25 | H35: =+F35+G35 -> 417685.25 | I35: =H35*(1+168480/7089080) -> 427612.01 | K35: =+I35+J35 -> 427612.01 | L35: =K35*(1+188880/9211560) -> 436380.05 | N35: =+L35+M35 -> 436380.05 | O35: =N35*(1+229880/10807440) -> 445662.09 | Q35: =+O35+P35 -> 445662.09 | R35: =Q35*(1+258720/12010320) -> 455262.31 | T35: =+R35+S35 -> 455262.31 | U35: =T35*(1+276600/13176040) -> 464819.47 | W35: =+U35+V35 -> 464819.47 | X35: =W35*(1+281720/15349640) -> 473350.54 | Z35: =+X35+Y35 -> 473350.54 | AA35: =Z35*(1+313600/16586360) -> 482300.23 | AC35: =+AA35+AB35 -> 482300.23 | AD35: =AC35*(1+321600/17662960) -> 491081.76 | AF35: =+AD35+AE35 -> 491081.76 | AG35: =AF35*(1+333320/18946560) -> 499721.18 | AI35: =+AG35+AH35 -> 499721.18 | AJ35: =AI35*(1+1/19279881) -> 499721.21 | AK35: =B35+D35+G35+J35+M35+P35+S35+V35+Y35+AB35+AE35+AH35 -> 410000 | AL35: =-AK35+AJ35 -> 89721.207 | AM35: =Tableau4[[#This Row],[EP TOTALE]]+Tableau4[[#This Row],[INTERETS]] -> 499721.21 | AN35: =Tableau4[[#This Row],[EP TOTALE]]*AK$40 -> 0
A36: AUTRES / FETE | C36: =B36*(1+38000/4317300) -> 0 | E36: =+D36+C36 -> 0 | F36: =E36*(1+57680/5852300) -> 0 | H36: =+F36+G36 -> 0 | I36: =H36*(1+168480/7089080) -> 0 | K36: =+I36+J36 -> 0 | L36: =K36*(1+188880/9211560) -> 0 | N36: =+L36+M36 -> 0 | O36: =N36*(1+229880/10807440) -> 0 | Q36: =+O36+P36 -> 0 | R36: =Q36*(1+258720/12010320) -> 0 | T36: =+R36+S36 -> 0 | U36: =T36*(1+276600/13176040) -> 0 | W36: =+U36+V36 -> 0 | X36: =W36*(1+281720/15349640) -> 0 | Z36: =+X36+Y36 -> 0 | AA36: =Z36*(1+313600/16586360) -> 0 | AC36: =+AA36+AB36 -> 0 | AD36: =AC36*(1+321600/17662960) -> 0 | AF36: =+AD36+AE36 -> 0 | AG36: =AF36*(1+333320/18946560) -> 0 | AI36: =+AG36+AH36 -> 0 | AJ36: =AI36*(1+1/19279881) -> 0 | AK36: =B36+D36+G36+J36+M36+P36+S36+V36+Y36+AB36+AE36+AH36 -> 0 | AL36: =-AK36+AJ36 -> 0 | AM36: =Tableau4[[#This Row],[EP TOTALE]]+Tableau4[[#This Row],[INTERETS]] -> 0 | AN36: =Tableau4[[#This Row],[EP TOTALE]]*AK$40 -> 0
A37: total | B37: =SUM(B2:B36) -> 4317300 | C37: =B37*(1+38000/4317300) -> 4355300 | D37: =SUM(D2:D36) -> 1497000 | E37: =+D37+C37 -> 5852300 | F37: =E37*(1+57680/5852300) -> 5909980 | G37: =+SUM(G2:G36) -> 1179100 | H37: =+F37+G37 -> 7089080 | I37: =H37*(1+168480/7089080) -> 7257560 | J37: =SUM(J2:J36) -> 1954000 | K37: =+I37+J37 -> 9211560 | L37: =K37*(1+188880/9211560) -> 9400440 | M37: =SUM(M2:M36) -> 1407000 | N37: =+L37+M37 -> 10807440 | O37: =N37*(1+229880/10807440) -> 11037320 | P37: =+SUM(P2:P36) -> 973000 | Q37: =+O37+P37 -> 12010320 | R37: =Q37*(1+258720/12010320) -> 12269040 | S37: =+SUM(S2:S36) -> 907000 | T37: =+R37+S37 -> 13176040 | U37: =T37*(1+276600/13176040) -> 13452640 | V37: =+SUM(V2:V36) -> 1897000 | W37: =+U37+V37 -> 15349640 | X37: =W37*(1+281720/15349640) -> 15631360 | Y37: =+SUM(Y2:Y36) -> 955000 | Z37: =+X37+Y37 -> 16586360 | AA37: =Z37*(1+313600/16586360) -> 16899960 | AB37: =+SUM(AB2:AB36) -> 763000 | AC37: =+AA37+AB37 -> 17662960 | AD37: =AC37*(1+321600/17662960) -> 17984560 | AE37: =+SUM(AE2:AE35) -> 962000 | AF37: =+AD37+AE37 -> 18946560 | AG37: =AF37*(1+333320/18946560) -> 19279880 | AH37: =+SUM(AH2:AH36) -> 0 | AI37: =+AG37+AH37 -> 19279880 | AJ37: =AI37*(1+1/19279881) -> 19279881 | AK37: =+SUM(AK2:AK36) -> 16811400 | AL37: =-AK37+AJ37 -> 2468481 | AM37: =Tableau4[[#This Row],[EP TOTALE]]+Tableau4[[#This Row],[INTERETS]] -> 19279881 | AN37: =Tableau4[[#This Row],[EP TOTALE]]*AK$40 -> 0
AJ38: =AJ40/AJ35 -> 0

Sheet insc+sec
A1: NOMS ET PRENOMS | B1: inscriptions | C1: SEC SEPT | D1: SEC OCT | E1: SEC NOV | F1: SEC DEC | G1: SEC JANV | H1: SEC FEV | I1: SEC MAR | J1: SEC AVR | K1: SEC MAI | L1: SEC JUIN | M1: SEC JUIL | N1: SEC AOUT | O1: TOTAL
A2: ABENG ZE Jean Claude | B2: 10000 | O2: =+SUM(C2:N2) -> 0
A3: BANGA NNA Israel | B3: 10000 | O3: =+SUM(C3:N3) -> 0
A4: BISSAI BI NOMBO Fabrice | B4: 10000 | O4: =+SUM(C4:N4) -> 0
A5: BOMBA FOUDA Mathieu | B5: 10000 | O5: =+SUM(C5:N5) -> 0
A6: EBOGO BIKOULA Gilbert | B6: 10000 | O6: =+SUM(C6:N6) -> 0
A7: ESSALA Etienne | B7: 10000 | O7: =+SUM(C7:N7) -> 0
A8: ETOA Yves | B8: 10000 | O8: =+SUM(C8:N8) -> 0
A9: EWALA Jacques Philippe | B9: 10000 | O9: =+SUM(C9:N9) -> 0
A10: FOTUE KAMGUE Kevin | B10: 10000 | O10: =+SUM(C10:N10) -> 0
A11: IPOULE Michel Landry | B11: 10000 | O11: =+SUM(C11:N11) -> 0
A12: ITOP Samuel | B12: 10000 | O12: =+SUM(C12:N12) -> 0
A13: LIKENG BALABA | B13: 10000 | O13: =+SUM(C13:N13) -> 0
... A33: ZE ANDJE Eric | B33: 10000 | O33: =+SUM(C33:N33) -> 0
A34: total | B34: =+SUM(B2:B33) -> 320000 | C34: =+SUM(C2:C33) -> 0 | D34: =+SUM(D2:D33) -> 0 | E34: =+SUM(E2:E33) -> 0 | F34: =+SUM(F2:F33) -> 0 | G34: =+SUM(G2:G33) -> 0 | H34: =+SUM(H2:H33) -> 0 | I34: =+SUM(I2:I33) -> 0 | ... N34: =+SUM(N2:N33) -> 0 | O34: =+SUM(C34:N34) -> 0

Sheet ep+int (2)
A1: NOMS ET PRENOMS | B1: EP AOUT | C1: EP AOUT+INT | D1: EP SEPT | E1: CUMUL1 | F1: EP +INT1 | G1: EP OCTO | H1: CUMUL2 | I1: EP +INT2 | J1: EP NOV | K1: CUMUL3 | L1: EP +INT3 | M1: EP DEC | N1: CUMUL4 | O1: EP+INT | P1: EP JANV | Q1: CUMUL5 | R1: EP+INT4 | S1: EP FEV | T1: CUMUL6 | U1: EP+INT5 | V1: EP MARS | W1: CUMUL7 | X1: EP+INT6 | Y1: EP AVRI | Z1: CUMUL8 | AA1: EP+INT7 | AB1: EP MAI | AC1: CUMUL9 | AD1: EP+INT8 | AE1: EP JUIN | AF1: CUMUL10 | AG1: EP+INT9 | AH1: EP JUILL | AI1: CUMUL11 | AJ1: EP+INT94 | AK1: EP TOTALE | AL1: INTERETS | AM1: N A P | AO1: N° | AP1: NOM | AQ1: EPARGNE | AR1: INTERET | AS1: TOTAL | AU1: REM PRETS
A2: ABENG ZE Jean Claude | B2: 94000 | C2: =B2*(1+(intérêts25!B$34)/(B$37)) -> 94827.369 | E2: =+D2+C2 -> 94827.369 | F2: =+E2*(1+(intérêts25!C$34)/(E$37)) -> 95761.983 | H2: =+F2+G2 -> 95761.983 | I2: =+H2*(1+(intérêts25!D$34)/(H$37)) -> 97983.841 | K2: =+I2+J2 -> 97983.841 | L2: =+K2*(1+(intérêts25!E$34)/(K$37)) -> 99419.19 | N2: =+L2+M2 -> 99419.19 | O2: =+N2*(1+(intérêts25!F$34)/(N$37)) -> 100583.43 | Q2: =+O2+P2 -> 100583.43 | R2: =+Q2*(1+(intérêts25!G$34)/(Q$37)) -> 101896.88 | T2: =+R2+S2 -> 101896.88 | U2: =+T2*(1+(intérêts25!H$34)/(T$37)) -> 103259.19 | W2: =+U2+V2 -> 103259.19 | X2: =+W2*(1+(intérêts25!I$34)/(W$37)) -> 104484.27 | Z2: =+X2+Y2 -> 104484.27 | AA2: =+Z2*(1+(intérêts25!J$34)/(Z$37)) -> 106403.75 | AC2: =+AA2+AB2 -> 106403.75 | AD2: =+AC2*(1+(intérêts25!K$34)/(AC$37)) -> 108237.93 | AF2: =+AD2+AE2 -> 108237.93 | AG2: =+AF2*(1+(intérêts25!L$34)/(AF$37)) -> 110106.29 | AI2: =+AG2+AH2 -> 110106.29 | AJ2: =+AI2*(1+(intérêts25!M$34)/(AI$37)) -> 110106.29 | AK2: =B2+D2+G2+J2+M2+P2+S2+V2+Y2+AB2+AE2+AH2 -> 94000 | AL2: =-AK2+AJ2 -> 16106.292 | AM2: =Tableau44[[#This Row],[EP TOTALE]]+Tableau44[[#This Row],[INTERETS]] -> 110106.29 | AO2: 1 | AP2: ABENG ZE Jean Claude | AQ2: 94000 | AR2: 16106.292 | AS2: 110106.29
A3: BANGA NNA Israel | B3: 129000 | C3: =B3*(1+(intérêts25!B$34)/(B$37)) -> 130135.43 | E3: =+D3+C3 -> 130135.43 | F3: =+E3*(1+(intérêts25!C$34)/(E$37)) -> 131418.04 | G3: 100000 | H3: =+F3+G3 -> 231418.04 | I3: =+H3*(1+(intérêts25!D$34)/(H$37)) -> 236787.37 | J3: 100000 | K3: =+I3+J3 -> 336787.37 | L3: =+K3*(1+(intérêts25!E$34)/(K$37)) -> 341720.92 | N3: =+L3+M3 -> 341720.92 | O3: =+N3*(1+(intérêts25!F$34)/(N$37)) -> 345722.6 | Q3: =+O3+P3 -> 345722.6 | R3: =+Q3*(1+(intérêts25!G$34)/(Q$37)) -> 350237.18 | T3: =+R3+S3 -> 350237.18 | U3: =+T3*(1+(intérêts25!H$34)/(T$37)) -> 354919.65 | W3: =+U3+V3 -> 354919.65 | X3: =+W3*(1+(intérêts25!I$34)/(W$37)) -> 359130.46 | Z3: =+X3+Y3 -> 359130.46 | AA3: =+Z3*(1+(intérêts25!J$34)/(Z$37)) -> 365728.04 | AC3: =+AA3+AB3 -> 365728.04 | AD3: =+AC3*(1+(intérêts25!K$34)/(AC$37)) -> 372032.46 | AF3: =+AD3+AE3 -> 372032.46 | AG3: =+AF3*(1+(intérêts25!L$34)/(AF$37)) -> 378454.33 | AI3: =+AG3+AH3 -> 378454.33 | AJ3: =+AI3*(1+(intérêts25!M$34)/(AI$37)) -> 378454.33 | AK3: =B3+D3+G3+J3+M3+P3+S3+V3+Y3+AB3+AE3+AH3 -> 329000 | AL3: =-AK3+AJ3 -> 49454.331 | AM3: =Tableau44[[#This Row],[EP TOTALE]]+Tableau44[[#This Row],[INTERETS]] -> 378454.33 | AO3: 2 | AP3: BANGA NNA Israel | AQ3: 329000 | AR3: 49454.331 | AS3: 378454.33
A4: BISSAI BI NOMBO Fabrice | B4: 107000 | C4: =B4*(1+(intérêts25!B$34)/(B$37)) -> 107941.79 | D4: 56000 | E4: =+D4+C4 -> 163941.79 | F4: =+E4*(1+(intérêts25!C$34)/(E$37)) -> 165557.6 | G4: 7000 | H4: =+F4+G4 -> 172557.6 | I4: =+H4*(1+(intérêts25!D$34)/(H$37)) -> 176561.26 | J4: 7000 | K4: =+I4+J4 -> 183561.26 | L4: =+K4*(1+(intérêts25!E$34)/(K$37)) -> 186250.21 | M4: 7000 | N4: =+L4+M4 -> 193250.21 | O4: =+N4*(1+(intérêts25!F$34)/(N$37)) -> 195513.25 | P4: 7000 | Q4: =+O4+P4 -> 202513.25 | R4: =+Q4*(1+(intérêts25!G$34)/(Q$37)) -> 205157.74 | S4: 7000 | T4: =+R4+S4 -> 212157.74 | U4: =+T4*(1+(intérêts25!H$34)/(T$37)) -> 214994.17 | V4: 7000 | W4: =+U4+V4 -> 221994.17 | X4: =+W4*(1+(intérêts25!I$34)/(W$37)) -> 224627.94 | Z4: =+X4+Y4 -> 224627.94 | AA4: =+Z4*(1+(intérêts25!J$34)/(Z$37)) -> 228754.57 | AC4: =+AA4+AB4 -> 228754.57 | AD4: =+AC4*(1+(intérêts25!K$34)/(AC$37)) -> 232697.85 | AE4: 8000 | AF4: =+AD4+AE4 -> 240697.85 | AG4: =+AF4*(1+(intérêts25!L$34)/(AF$37)) -> 244852.67 | AI4: =+AG4+AH4 -> 244852.67 | AJ4: =+AI4*(1+(intérêts25!M$34)/(AI$37)) -> 244852.67 | AK4: =B4+D4+G4+J4+M4+P4+S4+V4+Y4+AB4+AE4+AH4 -> 213000 | AL4: =-AK4+AJ4 -> 31852.673 | AM4: =Tableau44[[#This Row],[EP TOTALE]]+Tableau44[[#This Row],[INTERETS]] -> 244852.67 | AO4: 3 | AP4: BISSAI BI NOMBO Fabrice | AQ4: 213000 | AR4: 31852.673 | AS4: 244852.67
A5: BOMBA FOUDA Mathieu | B5: 94000 | C5: =B5*(1+(intérêts25!B$34)/(B$37)) -> 94827.369 | E5: =+D5+C5 -> 94827.369 | F5: =+E5*(1+(intérêts25!C$34)/(E$37)) -> 95761.983 | H5: =+F5+G5 -> 95761.983 | I5: =+H5*(1+(intérêts25!D$34)/(H$37)) -> 97983.841 | K5: =+I5+J5 -> 97983.841 | L5: =+K5*(1+(intérêts25!E$34)/(K$37)) -> 99419.19 | N5: =+L5+M5 -> 99419.19 | O5: =+N5*(1+(intérêts25!F$34)/(N$37)) -> 100583.43 | Q5: =+O5+P5 -> 100583.43 | R5: =+Q5*(1+(intérêts25!G$34)/(Q$37)) -> 101896.88 | T5: =+R5+S5 -> 101896.88 | U5: =+T5*(1+(intérêts25!H$34)/(T$37)) -> 103259.19 | W5: =+U5+V5 -> 103259.19 | X5: =+W5*(1+(intérêts25!I$34)/(W$37)) -> 104484.27 | Z5: =+X5+Y5 -> 104484.27 | AA5: =+Z5*(1+(intérêts25!J$34)/(Z$37)) -> 106403.75 | AC5: =+AA5+AB5 -> 106403.75 | AD5: =+AC5*(1+(intérêts25!K$34)/(AC$37)) -> 108237.93 | AE5: 8000 | AF5: =+AD5+AE5 -> 116237.93 | AG5: =+AF5*(1+(intérêts25!L$34)/(AF$37)) -> 118244.39 | AI5: =+AG5+AH5 -> 118244.39 | AJ5: =+AI5*(1+(intérêts25!M$34)/(AI$37)) -> 118244.39 | AK5: =B5+D5+G5+J5+M5+P5+S5+V5+Y5+AB5+AE5+AH5 -> 102000 | AL5: =-AK5+AJ5 -> 16244.385 | AM5: =Tableau44[[#This Row],[EP TOTALE]]+Tableau44[[#This Row],[INTERETS]] -> 118244.39 | AO5: 4 | AP5: BOMBA FOUDA Mathieu | AQ5: 102000 | AR5: 16244.385 | AS5: 118244.39
A6: EBOGO BIKOULA Gilbert | B6: 100000 | C6: =B6*(1+(intérêts25!B$34)/(B$37)) -> 100880.18 | E6: =+D6+C6 -> 100880.18 | F6: =+E6*(1+(intérêts25!C$34)/(E$37)) -> 101874.45 | H6: =+F6+G6 -> 101874.45 | I6: =+H6*(1+(intérêts25!D$34)/(H$37)) -> 104238.13 | K6: =+I6+J6 -> 104238.13 | L6: =+K6*(1+(intérêts25!E$34)/(K$37)) -> 105765.1 | N6: =+L6+M6 -> 105765.1 | O6: =+N6*(1+(intérêts25!F$34)/(N$37)) -> 107003.65 | Q6: =+O6+P6 -> 107003.65 | R6: =+Q6*(1+(intérêts25!G$34)/(Q$37)) -> 108400.94 | T6: =+R6+S6 -> 108400.94 | U6: =+T6*(1+(intérêts25!H$34)/(T$37)) -> 109850.2 | W6: =+U6+V6 -> 109850.2 | X6: =+W6*(1+(intérêts25!I$34)/(W$37)) -> 111153.47 | Z6: =+X6+Y6 -> 111153.47 | AA6: =+Z6*(1+(intérêts25!J$34)/(Z$37)) -> 113195.47 | AC6: =+AA6+AB6 -> 113195.47 | AD6: =+AC6*(1+(intérêts25!K$34)/(AC$37)) -> 115146.74 | AF6: =+AD6+AE6 -> 115146.74 | AG6: =+AF6*(1+(intérêts25!L$34)/(AF$37)) -> 117134.35 | AI6: =+AG6+AH6 -> 117134.35 | AJ6: =+AI6*(1+(intérêts25!M$34)/(AI$37)) -> 117134.35 | AK6: =B6+D6+G6+J6+M6+P6+S6+V6+Y6+AB6+AE6+AH6 -> 100000 | AL6: =-AK6+AJ6 -> 17134.354 | AM6: =Tableau44[[#This Row],[EP TOTALE]]+Tableau44[[#This Row],[INTERETS]] -> 117134.35 | AO6: 5 | AP6: EBOGO BIKOULA Gilbert | AQ6: 100000 | AR6: 17134.354 | AS6: 117134.35
A7: ESSALA Etienne | B7: 160000 | C7: =B7*(1+(intérêts25!B$34)/(B$37)) -> 161408.29 | E7: =+D7+C7 -> 161408.29 | F7: =+E7*(1+(intérêts25!C$34)/(E$37)) -> 162999.12 | H7: =+F7+G7 -> 162999.12 | I7: =+H7*(1+(intérêts25!D$34)/(H$37)) -> 166781.01 | J7: 40000 | K7: =+I7+J7 -> 206781.01 | L7: =+K7*(1+(intérêts25!E$34)/(K$37)) -> 209810.11 | N7: =+L7+M7 -> 209810.11 | O7: =+N7*(1+(intérêts25!F$34)/(N$37)) -> 212267.06 | P7: 10000 | Q7: =+O7+P7 -> 222267.06 | R7: =+Q7*(1+(intérêts25!G$34)/(Q$37)) -> 225169.51 | S7: 50000 | T7: =+R7+S7 -> 275169.51 | U7: =+T7*(1+(intérêts25!H$34)/(T$37)) -> 278848.37 | V7: 35000 | W7: =+U7+V7 -> 313848.37 | X7: =+W7*(1+(intérêts25!I$34)/(W$37)) -> 317571.9 | Z7: =+X7+Y7 -> 317571.9 | AA7: =+Z7*(1+(intérêts25!J$34)/(Z$37)) -> 323406.01 | AB7: 50000 | AC7: =+AA7+AB7 -> 373406.01 | AD7: =+AC7*(1+(intérêts25!K$34)/(AC$37)) -> 379842.79 | AF7: =+AD7+AE7 -> 379842.79 | AG7: =+AF7*(1+(intérêts25!L$34)/(AF$37)) -> 386399.48 | AI7: =+AG7+AH7 -> 386399.48 | AJ7: =+AI7*(1+(intérêts25!M$34)/(AI$37)) -> 386399.48 | AK7: =B7+D7+G7+J7+M7+P7+S7+V7+Y7+AB7+AE7+AH7 -> 345000 | AL7: =-AK7+AJ7 -> 41399.479 | AM7: =Tableau44[[#This Row],[EP TOTALE]]+Tableau44[[#This Row],[INTERETS]] -> 386399.48 | AO7: 6 | AP7: ESSALA Etienne | AQ7: 345000 | AR7: 41399.479 | AS7: 386399.48
A8: ETOA Yves | B8: 100000 | C8: =B8*(1+(intérêts25!B$34)/(B$37)) -> 100880.18 | E8: =+D8+C8 -> 100880.18 | F8: =+E8*(1+(intérêts25!C$34)/(E$37)) -> 101874.45 | G8: 176100 | H8: =+F8+G8 -> 277974.45 | I8: =+H8*(1+(intérêts25!D$34)/(H$37)) -> 284423.98 | J8: 1250000 | K8: =+I8+J8 -> 1534424 | L8: =+K8*(1+(intérêts25!E$34)/(K$37)) -> 1556901.5 | M8: 50000 | N8: =+L8+M8 -> 1606901.5 | O8: =+N8*(1+(intérêts25!F$34)/(N$37)) -> 1625718.9 | P8: 130000 | Q8: =+O8+P8 -> 1755718.9 | R8: =+Q8*(1+(intérêts25!G$34)/(Q$37)) -> 1778645.8 | S8: 50000 | T8: =+R8+S8 -> 1828645.8 | U8: =+T8*(1+(intérêts25!H$34)/(T$37)) -> 1853093.8 | V8: 1250000 | W8: =+U8+V8 -> 3103093.8 | X8: =+W8*(1+(intérêts25!I$34)/(W$37)) -> 3139909.2 | Y8: 100000 | Z8: =+X8+Y8 -> 3239909.2 | AA8: =+Z8*(1+(intérêts25!J$34)/(Z$37)) -> 3299429.5 | AB8: 100000 | AC8: =+AA8+AB8 -> 3399429.5 | AD8: =+AC8*(1+(intérêts25!K$34)/(AC$37)) -> 3458028.9 | AE8: 150000 | AF8: =+AD8+AE8 -> 3608028.9 | AG8: =+AF8*(1+(intérêts25!L$34)/(AF$37)) -> 3670309.2 | AI8: =+AG8+AH8 -> 3670309.2 | AJ8: =+AI8*(1+(intérêts25!M$34)/(AI$37)) -> 3670309.2 | AK8: =B8+D8+G8+J8+M8+P8+S8+V8+Y8+AB8+AE8+AH8 -> 3356100 | AL8: =-AK8+AJ8 -> 314209.21 | AM8: =Tableau44[[#This Row],[EP TOTALE]]+Tableau44[[#This Row],[INTERETS]] -> 3670309.2 | AO8: 7 | AP8: ETOA Yves | AQ8: 3356100 | AR8: 314209.21 | AS8: 3670309.2
A9: EWALA Jacques Philippe | B9: 19000 | C9: =B9*(1+(intérêts25!B$34)/(B$37)) -> 19167.234 | D9: 81000 | E9: =+D9+C9 -> 100167.23 | F9: =+E9*(1+(intérêts25!C$34)/(E$37)) -> 101154.48 | H9: =+F9+G9 -> 101154.48 | I9: =+H9*(1+(intérêts25!D$34)/(H$37)) -> 103501.45 | K9: =+I9+J9 -> 103501.45 | L9: =+K9*(1+(intérêts25!E$34)/(K$37)) -> 105017.63 | N9: =+L9+M9 -> 105017.63 | O9: =+N9*(1+(intérêts25!F$34)/(N$37)) -> 106247.42 | Q9: =+O9+P9 -> 106247.42 | R9: =+Q9*(1+(intérêts25!G$34)/(Q$37)) -> 107634.84 | T9: =+R9+S9 -> 107634.84 | U9: =+T9*(1+(intérêts25!H$34)/(T$37)) -> 109073.86 | W9: =+U9+V9 -> 109073.86 | X9: =+W9*(1+(intérêts25!I$34)/(W$37)) -> 110367.93 | Z9: =+X9+Y9 -> 110367.93 | AA9: =+Z9*(1+(intérêts25!J$34)/(Z$37)) -> 112395.49 | AB9: 0 | AC9: =+AA9+AB9 -> 112395.49 | AD9: =+AC9*(1+(intérêts25!K$34)/(AC$37)) -> 114332.97 | AF9: =+AD9+AE9 -> 114332.97 | AG9: =+AF9*(1+(intérêts25!L$34)/(AF$37)) -> 116306.54 | AI9: =+AG9+AH9 -> 116306.54 | AJ9: =+AI9*(1+(intérêts25!M$34)/(AI$37)) -> 116306.54 | AK9: =B9+D9+G9+J9+M9+P9+S9+V9+Y9+AB9+AE9+AH9 -> 100000 | AL9: =-AK9+AJ9 -> 16306.536 | AM9: =Tableau44[[#This Row],[EP TOTALE]]+Tableau44[[#This Row],[INTERETS]] -> 116306.54 | AO9: 8 | AP9: EWALA Jacques Philippe | AQ9: 100000 | AR9: 16306.536 | AS9: 116306.54
A10: FOTUE KAMGUE Kevin | B10: 100000 | C10: =B10*(1+(intérêts25!B$34)/(B$37)) -> 100880.18 | E10: =+D10+C10 -> 100880.18 | F10: =+E10*(1+(intérêts25!C$34)/(E$37)) -> 101874.45 | H10: =+F10+G10 -> 101874.45 | I10: =+H10*(1+(intérêts25!D$34)/(H$37)) -> 104238.13 | K10: =+I10+J10 -> 104238.13 | L10: =+K10*(1+(intérêts25!E$34)/(K$37)) -> 105765.1 | N10: =+L10+M10 -> 105765.1 | O10: =+N10*(1+(intérêts25!F$34)/(N$37)) -> 107003.65 | Q10: =+O10+P10 -> 107003.65 | R10: =+Q10*(1+(intérêts25!G$34)/(Q$37)) -> 108400.94 | T10: =+R10+S10 -> 108400.94 | U10: =+T10*(1+(intérêts25!H$34)/(T$37)) -> 109850.2 | W10: =+U10+V10 -> 109850.2 | X10: =+W10*(1+(intérêts25!I$34)/(W$37)) -> 111153.47 | Z10: =+X10+Y10 -> 111153.47 | AA10: =+Z10*(1+(intérêts25!J$34)/(Z$37)) -> 113195.47 | AC10: =+AA10+AB10 -> 113195.47 | AD10: =+AC10*(1+(intérêts25!K$34)/(AC$37)) -> 115146.74 | AF10: =+AD10+AE10 -> 115146.74 | AG10: =+AF10*(1+(intérêts25!L$34)/(AF$37)) -> 117134.35 | AI10: =+AG10+AH10 -> 117134.35 | AJ10: =+AI10*(1+(intérêts25!M$34)/(AI$37)) -> 117134.35 | AK10: =B10+D10+G10+J10+M10+P10+S10+V10+Y10+AB10+AE10+AH10 -> 100000 | AL10: =-AK10+AJ10 -> 17134.354 | AM10: =Tableau44[[#This Row],[EP TOTALE]]+Tableau44[[#This Row],[INTERETS]] -> 117134.35 | AO10: 9 | AP10: FOTUE KAMGUE Kevin | AQ10: 100000 | AR10: 17134.354 | AS10: 117134.35
A11: IPOULE Michel Landry | B11: 94000 | C11: =B11*(1+(intérêts25!B$34)/(B$37)) -> 94827.369 | E11: =+D11+C11 -> 94827.369 | F11: =+E11*(1+(intérêts25!C$34)/(E$37)) -> 95761.983 | H11: =+F11+G11 -> 95761.983 | I11: =+H11*(1+(intérêts25!D$34)/(H$37)) -> 97983.841 | K11: =+I11+J11 -> 97983.841 | L11: =+K11*(1+(intérêts25!E$34)/(K$37)) -> 99419.19 | N11: =+L11+M11 -> 99419.19 | O11: =+N11*(1+(intérêts25!F$34)/(N$37)) -> 100583.43 | Q11: =+O11+P11 -> 100583.43 | R11: =+Q11*(1+(intérêts25!G$34)/(Q$37)) -> 101896.88 | T11: =+R11+S11 -> 101896.88 | U11: =+T11*(1+(intérêts25!H$34)/(T$37)) -> 103259.19 | W11: =+U11+V11 -> 103259.19 | X11: =+W11*(1+(intérêts25!I$34)/(W$37)) -> 104484.27 | Z11: =+X11+Y11 -> 104484.27 | AA11: =+Z11*(1+(intérêts25!J$34)/(Z$37)) -> 106403.75 | AB11: 6000 | AC11: =+AA11+AB11 -> 112403.75 | AD11: =+AC11*(1+(intérêts25!K$34)/(AC$37)) -> 114341.36 | AF11: =+AD11+AE11 -> 114341.36 | AG11: =+AF11*(1+(intérêts25!L$34)/(AF$37)) -> 116315.08 | AI11: =+AG11+AH11 -> 116315.08 | AJ11: =+AI11*(1+(intérêts25!M$34)/(AI$37)) -> 116315.08 | AK11: =B11+D11+G11+J11+M11+P11+S11+V11+Y11+AB11+AE11+AH11 -> 100000 | AL11: =-AK11+AJ11 -> 16315.075 | AM11: =Tableau44[[#This Row],[EP TOTALE]]+Tableau44[[#This Row],[INTERETS]] -> 116315.08 | AO11: 10 | AP11: IPOULE Michel Landry | AQ11: 100000 | AR11: 16315.075 | AS11: 116315.08
A12: ITOP Samuel | B12: 200000 | C12: =B12*(1+(intérêts25!B$34)/(B$37)) -> 201760.36 | D12: 100000 | E12: =+D12+C12 -> 301760.36 | F12: =+E12*(1+(intérêts25!C$34)/(E$37)) -> 304734.5 | G12: 200000 | H12: =+F12+G12 -> 504734.5 | I12: =+H12*(1+(intérêts25!D$34)/(H$37)) -> 516445.29 | J12: 200000 | K12: =+I12+J12 -> 716445.29 | L12: =+K12*(1+(intérêts25!E$34)/(K$37)) -> 726940.37 | M12: 100000 | N12: =+L12+M12 -> 826940.37 | O12: =+N12*(1+(intérêts25!F$34)/(N$37)) -> 836624.16 | P12: 100000 | Q12: =+O12+P12 -> 936624.16 | R12: =+Q12*(1+(intérêts25!G$34)/(Q$37)) -> 948854.96 | S12: 100000 | T12: =+R12+S12 -> 1048855 | U12: =+T12*(1+(intérêts25!H$34)/(T$37)) -> 1062877.6 | V12: 100000 | W12: =+U12+V12 -> 1162877.6 | X12: =+W12*(1+(intérêts25!I$34)/(W$37)) -> 1176674.1 | Y12: 100000 | Z12: =+X12+Y12 -> 1276674.1 | AA12: =+Z12*(1+(intérêts25!J$34)/(Z$37)) -> 1300127.8 | AB12: 100000 | AC12: =+AA12+AB12 -> 1400127.8 | AD12: =+AC12*(1+(intérêts25!K$34)/(AC$37)) -> 1424263.2 | AE12: 100000 | AF12: =+AD12+AE12 -> 1524263.2 | AG12: =+AF12*(1+(intérêts25!L$34)/(AF$37)) -> 1550574.4 | AI12: =+AG12+AH12 -> 1550574.4 | AJ12: =+AI12*(1+(intérêts25!M$34)/(AI$37)) -> 1550574.4 | AK12: =B12+D12+G12+J12+M12+P12+S12+V12+Y12+AB12+AE12+AH12 -> 1400000 | AL12: =-AK12+AJ12 -> 150574.44 | AM12: =Tableau44[[#This Row],[EP TOTALE]]+Tableau44[[#This Row],[INTERETS]] -> 1550574.4 | AO12: 11 | AP12: ITOP Samuel | AQ12: 1400000 | AR12: 150574.44 | AS12: 1550574.4
